Workbook

Sheet Summary
A1: Percent Error = Absolute value of [(Difference) / (4p2\normal.PRN)] x 100%
B3: Sheet | C3: SSA | E3: SST | I3: TRA
B4: Column | C4: =SSA!C4 -> Airflow | D4: =SSA!D4 -> AirVel | E4: =SST!D4 -> AirTemp | F4: =SST!E4 -> Humidity | G4: =SST!F4 -> Sensible | H4: =SST!G4 -> Latent | I4: =TRA!C4 -> RTE | J4: =TRA!D4 -> TYP | K4: =TRA!E4 -> Location | L4: =TRA!F4 -> Speed | M4: =TRA!G4 -> Accel | N4: =TRA!H4 -> Drag_KN | O4: =TRA!I4 -> Drag_COEFF | P4: =TRA!J4 -> Tractive | ... X4: =TRA!R4 -> H_Reject
B5: =SSA!B5 -> count | C5: =SSA!C5 -> 120 | D5: =SSA!D5 -> 120 | E5: =SST!D5 -> 150 | F5: =SST!E5 -> 150 | G5: =SST!F5 -> 6 | H5: =SST!G5 -> 6 | I5: =TRA!C5 -> 25 | J5: =TRA!D5 -> 25 | K5: =TRA!E5 -> 25 | L5: =TRA!F5 -> 0 | M5: =TRA!G5 -> 0 | N5: =TRA!H5 -> 24 | O5: =TRA!I5 -> 0 | P5: =TRA!J5 -> 0 | ... X5: =TRA!R5 -> 25
B6: Mean | C6: =SSA!C6 -> 5.8339705e-05 | D6: =SSA!D6 -> 0 | E6: =SST!D6 -> 0.01109174 | F6: =SST!E6 -> 0.092889756 | G6: =SST!F6 -> 0 | H6: =SST!G6 -> 0 | I6: =TRA!C6 -> 0 | J6: =TRA!D6 -> 0 | K6: =TRA!E6 -> 0 | L6: =TRA!F6 -> 0 | M6: =TRA!G6 -> 0 | N6: =TRA!H6 -> 0 | O6: =TRA!I6 -> 0 | P6: =TRA!J6 -> 0 | ... X6: =TRA!R6 -> 0
B7: =SSA!B7 -> std | C7: =SSA!C7 -> 9.3281477e-05 | D7: =SSA!D7 -> 0 | E7: =SST!D7 -> 0.01386222 | F7: =SST!E7 -> 0.089911095 | G7: =SST!F7 -> 0 | H7: =SST!G7 -> 0 | I7: =TRA!C7 -> 0 | J7: =TRA!D7 -> 0 | K7: =TRA!E7 -> 0 | L7: =TRA!F7 -> 0 | M7: =TRA!G7 -> 0 | N7: =TRA!H7 -> 0 | O7: =TRA!I7 -> 0 | P7: =TRA!J7 -> 0 | ... X7: =TRA!R7 -> 0
B8: =SSA!B8 -> min | C8: =SSA!C8 -> 0 | D8: =SSA!D8 -> 0 | E8: =SST!D8 -> 0 | F8: =SST!E8 -> 0 | G8: =SST!F8 -> 0 | H8: =SST!G8 -> 0 | I8: =TRA!C8 -> 0 | J8: =TRA!D8 -> 0 | K8: =TRA!E8 -> 0 | L8: =TRA!F8 -> 0 | M8: =TRA!G8 -> 0 | N8: =TRA!H8 -> 0 | O8: =TRA!I8 -> 0 | P8: =TRA!J8 -> 0 | ... X8: =TRA!R8 -> 0
B9: =SSA!B9 -> 25% | C9: =SSA!C9 -> 0 | D9: =SSA!D9 -> 0 | E9: =SST!D9 -> 0 | F9: =SST!E9 -> 0.064102564 | G9: =SST!F9 -> 0 | H9: =SST!G9 -> 0 | I9: =TRA!C9 -> 0 | J9: =TRA!D9 -> 0 | K9: =TRA!E9 -> 0 | L9: =TRA!F9 -> 0 | M9: =TRA!G9 -> 0 | N9: =TRA!H9 -> 0 | O9: =TRA!I9 -> 0 | P9: =TRA!J9 -> 0 | ... X9: =TRA!R9 -> 0
B10: =SSA!B10 -> 50% | C10: =SSA!C10 -> 0 | D10: =SSA!D10 -> 0 | E10: =SST!D10 -> 0.0095606576 | F10: =SST!E10 -> 0.064516129 | G10: =SST!F10 -> 0 | H10: =SST!G10 -> 0 | I10: =TRA!C10 -> 0 | J10: =TRA!D10 -> 0 | K10: =TRA!E10 -> 0 | L10: =TRA!F10 -> 0 | M10: =TRA!G10 -> 0 | N10: =TRA!H10 -> 0 | O10: =TRA!I10 -> 0 | P10: =TRA!J10 -> 0 | ... X10: =TRA!R10 -> 0
B11: =SSA!B11 -> 75% | C11: =SSA!C11 -> 0.0001278388 | D11: =SSA!D11 -> 0 | E11: =SST!D11 -> 0.011764706 | F11: =SST!E11 -> 0.12820513 | G11: =SST!F11 -> 0 | H11: =SST!G11 -> 0 | I11: =TRA!C11 -> 0 | J11: =TRA!D11 -> 0 | K11: =TRA!E11 -> 0 | L11: =TRA!F11 -> 0 | M11: =TRA!G11 -> 0 | N11: =TRA!H11 -> 0 | O11: =TRA!I11 -> 0 | P11: =TRA!J11 -> 0 | ... X11: =TRA!R11 -> 0
B12: Max | C12: =SSA!C12 -> 0.00043737517 | D12: =SSA!D12 -> 0 | E12: =SST!D12 -> 0.058823529 | F12: =SST!E12 -> 0.32051282 | G12: =SST!F12 -> 0 | H12: =SST!G12 -> 0 | I12: =TRA!C12 -> 0 | J12: =TRA!D12 -> 0 | K12: =TRA!E12 -> 0 | L12: =TRA!F12 -> 0 | M12: =TRA!G12 -> 0 | N12: =TRA!H12 -> 0 | O12: =TRA!I12 -> 0 | P12: =TRA!J12 -> 0 | ... X12: =TRA!R12 -> 0
A14: Percent Error = Absolute value of [(Difference) / (4p2\normal.PRN)] x 100%
A15: {=TRANSPOSE(B3:X12)} -> Sheet | B15: Column | C15: count | D15: Mean | E15: std | F15: min | G15: 25% | H15: 50% | I15: 75% | J15: Max | K15: Description | L15: Unit
A16: SSA | B16: Airflow | C16: 120 | D16: 5.8339705e-05 | E16: 9.3281477e-05 | F16: 0 | G16: 0 | H16: 0 | I16: 0.0001278388 | J16: 0.00043737517 | K16: =VLOOKUP($B16,[1]Legend!$B$2:$E$110,2,FALSE) -> Section Air Flow Rate | L16: =VLOOKUP($B16,[1]Legend!$B$2:$E$110,4,FALSE) -> kCFM
A17: 0 | B17: AirVel | C17: 120 | D17: 0 | E17: 0 | F17: 0 | G17: 0 | H17: 0 | I17: 0 | J17: 0 | K17: =VLOOKUP($B17,[1]Legend!$B$2:$E$110,2,FALSE) -> Bulk Air Velocity | L17: =VLOOKUP($B17,[1]Legend!$B$2:$E$110,4,FALSE) -> FPM
A18: SST | B18: AirTemp | C18: 150 | D18: 0.01109174 | E18: 0.01386222 | F18: 0 | G18: 0 | H18: 0.0095606576 | I18: 0.011764706 | J18: 0.058823529 | K18: =VLOOKUP($B18,[1]Legend!$B$2:$E$110,2,FALSE) -> Air Dry-Bulb Temperature | L18: =VLOOKUP($B18,[1]Legend!$B$2:$E$110,4,FALSE) -> °F
A19: 0 | B19: Humidity | C19: 150 | D19: 0.092889756 | E19: 0.089911095 | F19: 0 | G19: 0.064102564 | H19: 0.064516129 | I19: 0.12820513 | J19: 0.32051282 | K19: =VLOOKUP($B19,[1]Legend!$B$2:$E$110,2,FALSE) -> 1 - Humidity Ratio | L19: =VLOOKUP($B19,[1]Legend!$B$2:$E$110,4,FALSE) -> °F
A20: 0 | B20: Sensible | C20: 6 | D20: 0 | E20: 0 | F20: 0 | G20: 0 | H20: 0 | I20: 0 | J20: 0 | K20: =VLOOKUP($B20,[1]Legend!$B$2:$E$110,2,FALSE) -> Total Sensible Heat Load | L20: =VLOOKUP($B20,[1]Legend!$B$2:$E$110,4,FALSE) -> BTU/sec
A21: 0 | B21: Latent | C21: 6 | D21: 0 | E21: 0 | F21: 0 | G21: 0 | H21: 0 | I21: 0 | J21: 0 | K21: =VLOOKUP($B21,[1]Legend!$B$2:$E$110,2,FALSE) -> Total Latent Heat Load | L21: =VLOOKUP($B21,[1]Legend!$B$2:$E$110,4,FALSE) -> BTU/sec
A22: TRA | B22: RTE | C22: 25 | D22: 0 | E22: 0 | F22: 0 | G22: 0 | H22: 0 | I22: 0 | J22: 0 | K22: =VLOOKUP($B22,[1]Legend!$B$2:$E$110,2,FALSE) -> Train route | L22: =VLOOKUP($B22,[1]Legend!$B$2:$E$110,4,FALSE) -> #
A23: 0 | B23: TYP | C23: 25 | D23: 0 | E23: 0 | F23: 0 | G23: 0 | H23: 0 | I23: 0 | J23: 0 | K23: =VLOOKUP($B23,[1]Legend!$B$2:$E$110,2,FALSE) -> Train Type | L23: =VLOOKUP($B23,[1]Legend!$B$2:$E$110,4,FALSE) -> #
A24: 0 | B24: Location | C24: 25 | D24: 0 | E24: 0 | F24: 0 | G24: 0 | H24: 0 | I24: 0 | J24: 0 | K24: =VLOOKUP($B24,[1]Legend!$B$2:$E$110,2,FALSE) -> Train Location | L24: =VLOOKUP($B24,[1]Legend!$B$2:$E$110,4,FALSE) -> ft
A25: 0 | B25: Speed | C25: 0 | D25: 0 | E25: 0 | F25: 0 | G25: 0 | H25: 0 | I25: 0 | J25: 0 | K25: =VLOOKUP($B25,[1]Legend!$B$2:$E$110,2,FALSE) -> Train Speed | L25: =VLOOKUP($B25,[1]Legend!$B$2:$E$110,4,FALSE) -> mph
A26: 0 | B26: Accel | C26: 0 | D26: 0 | E26: 0 | F26: 0 | G26: 0 | H26: 0 | I26: 0 | J26: 0 | K26: =VLOOKUP($B26,[1]Legend!$B$2:$E$110,2,FALSE) -> Train Acceleration | L26: =VLOOKUP($B26,[1]Legend!$B$2:$E$110,4,FALSE) -> mph/sec
A27: 0 | B27: Drag_KN | C27: 24 | D27: 0 | E27: 0 | F27: 0 | G27: 0 | H27: 0 | I27: 0 | J27: 0 | K27: =VLOOKUP($B27,[1]Legend!$B$2:$E$110,2,FALSE) -> Air Drag (KN) | L27: =VLOOKUP($B27,[1]Legend!$B$2:$E$110,4,FALSE) -> lbs
A28: 0 | B28: Drag_COEFF | C28: 0 | D28: 0 | E28: 0 | F28: 0 | G28: 0 | H28: 0 | I28: 0 | J28: 0 | K28: =VLOOKUP($B28,[1]Legend!$B$2:$E$110,2,FALSE) -> Air Drag (COEFF) | L28: =VLOOKUP($B28,[1]Legend!$B$2:$E$110,4,FALSE) -> #
A29: 0 | B29: Tractive | C29: 0 | D29: 0 | E29: 0 | F29: 0 | G29: 0 | H29: 0 | I29: 0 | J29: 0 | K29: =VLOOKUP($B29,[1]Legend!$B$2:$E$110,2,FALSE) -> Tractive Effort | L29: =VLOOKUP($B29,[1]Legend!$B$2:$E$110,4,FALSE) -> lbs/motor
A30: 0 | B30: M_Current | C30: 0 | D30: 0 | E30: 0 | F30: 0 | G30: 0 | H30: 0 | I30: 0 | J30: 0 | K30: =VLOOKUP($B30,[1]Legend!$B$2:$E$110,2,FALSE) -> Motor Current | L30: =VLOOKUP($B30,[1]Legend!$B$2:$E$110,4,FALSE) -> amps
A31: 0 | B31: L_Current | C31: 0 | D31: 0 | E31: 0 | F31: 0 | G31: 0 | H31: 0 | I31: 0 | J31: 0 | K31: =VLOOKUP($B31,[1]Legend!$B$2:$E$110,2,FALSE) -> Line Current | L31: =VLOOKUP($B31,[1]Legend!$B$2:$E$110,4,FALSE) -> amps
A32: 0 | B32: FLY | C32: 0 | D32: 0 | E32: 0 | F32: 0 | G32: 0 | H32: 0 | I32: 0 | J32: 0 | K32: =VLOOKUP($B32,[1]Legend!$B$2:$E$110,2,FALSE) -> Fly Wheel | L32: =VLOOKUP($B32,[1]Legend!$B$2:$E$110,4,FALSE) -> RPM
A33: 0 | B33: M_Eff | C33: 0 | D33: 0 | E33: 0 | F33: 0 | G33: 0 | H33: 0 | I33: 0 | J33: 0 | K33: =VLOOKUP($B33,[1]Legend!$B$2:$E$110,2,FALSE) -> Motor Efficiency | L33: =VLOOKUP($B33,[1]Legend!$B$2:$E$110,4,FALSE) -> 0
A34: 0 | B34: G_Accel | C34: 25 | D34: 0 | E34: 0 | F34: 0 | G34: 0 | H34: 0 | I34: 0 | J34: 0 | K34: =VLOOKUP($B34,[1]Legend!$B$2:$E$110,2,FALSE) -> Grid Temperature Acceleration | L34: =VLOOKUP($B34,[1]Legend!$B$2:$E$110,4,FALSE) -> °F
... A37: 0 | B37: H_Reject | C37: 25 | D37: 0 | E37: 0 | F37: 0 | G37: 0 | H37: 0 | I37: 0 | J37: 0 | K37: =VLOOKUP($B37,[1]Legend!$B$2:$E$110,2,FALSE) -> Heat rejected | L37: =VLOOKUP($B37,[1]Legend!$B$2:$E$110,4,FALSE) -> BTU/SEC-FT

Sheet Legend
A1: Sheet Name | B1: Heading | C1: Full description | D1: SI Unit | E1: IP Unit | F1: Note
A2: SSA | B2: Second-by-second aerodynamic data
B3: Time | C3: Simulation Time | D3: Sec | E3: Sec
B4: Segment | C4: Segment numbers | D4: # | E4: #
B5: ID | C5: Title | F5: Time-Segement (TTT-SSS)
B6: Title
B7: Airflow | C7: Section Air Flow Rate | D7: m3/s | E7: kCFM | F7: CFM is divided by 1,000 to convert to kcfm
B8: AirVel | C8: Bulk Air Velocity | D8: m/s | E8: FPM
A9: SST | B9: Second-by-second thermodynamic data
B10: Time | C10: Simulation Time | D10: Sec | E10: Sec
B11: Segment | C11: Segment numbers | D11: # | E11: #
B12: Sub | C12: Sub-segment number | D12: # | E12: #
B13: ID
B14: Sensible | C14: Total Sensible Heat Load | D14: W | E14: BTU/sec
B15: Latent | C15: Total Latent Heat Load | D15: W | E15: BTU/sec
B16: AirTemp | C16: Air Dry-Bulb Temperature | D16: °C | E16: °F
B17: Humidity | C17: 1 - Humidity Ratio | D17: kg/kg | E17: °F
B18: WallTemp | C18: Wall Surface Temperature | D18: °C | E18: °F
B19: WallConvection | C19: Heat Transfer to Wall by Convection | D19: W | E19: BTU/Hr
B20: WallRadiation | C20: Heat Transfer to Wall by Radiation | D20: W | E20: BTU/Hr
B21: FluidTemp | C21: Working Fluid Temperature | D21: °C
B22: FuildHeat | C22: Heat Absorbed by Cooling Pipe | D22: W
A23: TRA | B23: Secod-by-second Train data
B24: Time | C24: Time | D24: Sec | E24: Sec
B25: Number | C25: Train ID Number | D25: # | E25: #
B26: RTE | C26: Train route | D26: # | E26: #
B27: TYP | C27: Train Type | D27: # | E27: #
B28: Location | C28: Train Location | D28: m | E28: ft
B29: Speed | C29: Train Speed | D29: kph | E29: mph
B30: Accel | C30: Train Acceleration | D30: m/s2 | E30: mph/sec
B31: Drag_KN | C31: Air Drag (KN) | D31: kN | E31: lbs
B32: Drag_COEFF | C32: Air Drag (COEFF) | D32: # | E32: #
B33: Tractive | C33: Tractive Effort | D33: N/motor | E33: lbs/motor
B34: M_Current | C34: Motor Current | D34: amps | E34: amps
B35: L_Current | C35: Line Current | D35: amps | E35: amps
B36: FLY | C36: Fly Wheel | D36: RPM | E36: RPM
B37: M_Eff | C37: Motor Efficiency | D37: %
B38: G_Accel | C38: Grid Temperature Acceleration | D38: °C | E38: °F
B39: G_Decel | C39: Grid Temperature Deceleration | D39: °C | E39: °F
B40: H_Gen | C40: Heat generated | D40: W/m | E40: BTU/SEC-FT
...

Sheet SSA
A1: Next-Vis Sheet: SSA
A2: Summary
A3: Percent Error = Absolute value of [(Difference) / (4p2\inferno.PRN)] x 100% | F3: Difference = (4p2\inferno4p2.out) - (4p2\inferno.PRN)
C4: Airflow | D4: AirVel | H4: Airflow | I4: AirVel
B5: count | C5: 120 | D5: 120 | G5: count | H5: 125 | I5: 125
B6: mean | C6: 5.8339705e-05 | D6: 0 | G6: mean | H6: -3.44e-05 | I6: 0
B7: std | C7: 9.3281477e-05 | D7: 0 | G7: std | H7: 7.6310064e-05 | I7: 0
B8: min | C8: 0 | D8: 0 | G8: min | H8: -0.0003 | I8: 0
B9: 25% | C9: 0 | D9: 0 | G9: 25% | H9: -0.0001 | I9: 0
B10: 50% | C10: 0 | D10: 0 | G10: 50% | H10: 0 | I10: 0
B11: 75% | C11: 0.0001278388 | D11: 0 | G11: 75% | H11: 0 | I11: 0
B12: max | C12: 0.00043737517 | D12: 0 | G12: max | H12: 0.0002 | I12: 0
A13: Data
A14: Percent Error = Absolute value of [(Difference) / (4p2\inferno.PRN)] x 100% | F14: Difference = (4p2\inferno4p2.out) - (4p2\inferno.PRN) | K14: 4p2\inferno4p2.out | P14: 4p2\inferno.PRN
A15: Time | B15: Segment | C15: Airflow | D15: AirVel | F15: Time | G15: Segment | H15: Airflow | I15: AirVel | K15: Time | L15: Segment | M15: Airflow | N15: AirVel | P15: Time | Q15: Segment | R15: Airflow | S15: AirVel
A16: 0 | B16: 1 | F16: 0 | G16: 1 | H16: 0 | I16: 0 | K16: 0 | L16: 1 | M16: 0 | N16: 0 | P16: 0 | Q16: 1 | R16: 0 | S16: 0
A17: 0 | B17: 2 | F17: 0 | G17: 2 | H17: 0 | I17: 0 | K17: 0 | L17: 2 | M17: 0 | N17: 0 | P17: 0 | Q17: 2 | R17: 0 | S17: 0
A18: 0 | B18: 3 | F18: 0 | G18: 3 | H18: 0 | I18: 0 | K18: 0 | L18: 3 | M18: 0 | N18: 0 | P18: 0 | Q18: 3 | R18: 0 | S18: 0
A19: 0 | B19: 4 | F19: 0 | G19: 4 | H19: 0 | I19: 0 | K19: 0 | L19: 4 | M19: 0 | N19: 0 | P19: 0 | Q19: 4 | R19: 0 | S19: 0
A20: 0 | B20: 5 | F20: 0 | G20: 5 | H20: 0 | I20: 0 | K20: 0 | L20: 5 | M20: 0 | N20: 0 | P20: 0 | Q20: 5 | R20: 0 | S20: 0
A21: 10 | B21: 1 | C21: 0 | D21: 0 | F21: 10 | G21: 1 | H21: 0 | I21: 0 | K21: 10 | L21: 1 | M21: 153.1329 | N21: 811.5 | P21: 10 | Q21: 1 | R21: 153.1329 | S21: 811.5
A22: 10 | B22: 2 | C22: 0 | D22: 0 | F22: 10 | G22: 2 | H22: 0 | I22: 0 | K22: 10 | L22: 2 | M22: -110.7095 | N22: -586.7 | P22: 10 | Q22: 2 | R22: -110.7095 | S22: -586.7
A23: 10 | B23: 3 | C23: 0 | D23: 0 | F23: 10 | G23: 3 | H23: 0 | I23: 0 | K23: 10 | L23: 3 | M23: -110.7095 | N23: -586.7 | P23: 10 | Q23: 3 | R23: -110.7095 | S23: -586.7
A24: 10 | B24: 4 | C24: 0 | D24: 0 | F24: 10 | G24: 4 | H24: 0 | I24: 0 | K24: 10 | L24: 4 | M24: -110.7095 | N24: -586.7 | P24: 10 | Q24: 4 | R24: -110.7095 | S24: -586.7
A25: 10 | B25: 5 | C25: 0 | D25: 0 | F25: 10 | G25: 5 | H25: 0 | I25: 0 | K25: 10 | L25: 5 | M25: 263.8424 | N25: 879.5 | P25: 10 | Q25: 5 | R25: 263.8424 | S25: 879.5
A26: 20 | B26: 1 | C26: 5.130531e-05 | D26: 0 | F26: 20 | G26: 1 | H26: -0.0001 | I26: 0 | K26: 20 | L26: 1 | M26: 194.9115 | N26: 1032.9 | P26: 20 | Q26: 1 | R26: 194.9116 | S26: 1032.9
A27: 20 | B27: 2 | C27: 9.708785e-05 | D27: 0 | F27: 20 | G27: 2 | H27: -0.0001 | I27: 0 | K27: 20 | L27: 2 | M27: -102.9996 | N27: -545.8 | P27: 20 | Q27: 2 | R27: -102.9995 | S27: -545.8
A28: 20 | B28: 3 | C28: 9.708785e-05 | D28: 0 | F28: 20 | G28: 3 | H28: -0.0001 | I28: 0 | K28: 20 | L28: 3 | M28: -102.9996 | N28: -545.8 | P28: 20 | Q28: 3 | R28: -102.9995 | S28: -545.8
A29: 20 | B29: 4 | C29: 9.708785e-05 | D29: 0 | F29: 20 | G29: 4 | H29: -0.0001 | I29: 0 | K29: 20 | L29: 4 | M29: -102.9996 | N29: -545.8 | P29: 20 | Q29: 4 | R29: -102.9995 | S29: -545.8
A30: 20 | B30: 5 | C30: 0 | D30: 0 | F30: 20 | G30: 5 | H30: 0 | I30: 0 | K30: 20 | L30: 5 | M30: 297.9111 | N30: 993 | P30: 20 | Q30: 5 | R30: 297.9111 | S30: 993
A31: 30 | B31: 1 | C31: 0 | D31: 0 | F31: 30 | G31: 1 | H31: 0 | I31: 0 | K31: 30 | L31: 1 | M31: 206.1882 | N31: 1092.7 | P31: 30 | Q31: 1 | R31: 206.1882 | S31: 1092.7
A32: 30 | B32: 2 | C32: 0 | D32: 0 | F32: 30 | G32: 2 | H32: 0 | I32: 0 | K32: 30 | L32: 2 | M32: -92.0919 | N32: -488 | P32: 30 | Q32: 2 | R32: -92.0919 | S32: -488
... A140: 500 | B140: 5 | C140: 0 | D140: 0 | F140: 500 | G140: 5 | H140: 0 | I140: 0 | K140: 500 | L140: 5 | M140: 285.9701 | N140: 953.2 | P140: 500 | Q140: 5 | R140: 285.9701 | S140: 953.2

Sheet SST
A1: Next-Vis Sheet: SST
A2: Summary
B3: Percent Error = Absolute value of [(Difference) / (4p2\inferno.PRN)] x 100% | L3: Difference = (4p2\inferno4p2.out) - (4p2\inferno.PRN)
D4: AirTemp | E4: Humidity | F4: Sensible | G4: Latent | H4: WallTemp | I4: WallConvection | J4: WallRadiation | O4: AirTemp | P4: Humidity | Q4: Sensible | R4: Latent | S4: WallTemp | T4: WallConvection | U4: WallRadiation
C5: count | D5: 150 | E5: 150 | F5: 6 | G5: 6 | H5: 450 | I5: 373 | J5: 373 | N5: count | O5: 150 | P5: 150 | Q5: 28 | R5: 28 | S5: 450 | T5: 450 | U5: 450
C6: mean | D6: 0.01109174 | E6: 0.092889756 | F6: 0 | G6: 0 | H6: 5.2312199e-05 | I6: 0.26864568 | J6: 0.00093791791 | N6: mean | O6: 0.0036 | P6: 4.8e-06 | Q6: 0 | R6: 0 | S6: -0.00022222222 | T6: 0.038888889 | U6: -0.16644444
C7: std | D7: 0.01386222 | E7: 0.089911095 | F7: 0 | G7: 0 | H7: 0.0011097093 | I7: 5.1777762 | J7: 0.0054977728 | N7: std | O7: 0.020143112 | P7: 1.9754194e-05 | Q7: 0 | R7: 0 | S7: 0.0047140452 | T7: 1.426202 | U7: 0.62273789
C8: min | D8: 0 | E8: 0 | F8: 0 | G8: 0 | H8: 0 | I8: 0 | J8: 0 | N8: min | O8: -0.05 | P8: -5e-05 | Q8: 0 | R8: 0 | S8: -0.1 | T8: -8.8 | U8: -6
C9: 25% | D9: 0 | E9: 0.064102564 | F9: 0 | G9: 0 | H9: 0 | I9: 2.0224052e-05 | J9: 0 | N9: 25% | O9: 0 | P9: 0 | Q9: 0 | R9: 0 | S9: 0 | T9: -0.2 | U9: -0.1
C10: 50% | D10: 0.0095606576 | E10: 0.064516129 | F10: 0 | G10: 0 | H10: 0 | I10: 5.3852384e-05 | J10: 3.6071054e-05 | N10: 50% | O10: 0 | P10: 1e-05 | Q10: 0 | R10: 0 | S10: 0 | T10: 0 | U10: 0
C11: 75% | D11: 0.011764706 | E11: 0.12820513 | F11: 0 | G11: 0 | H11: 0 | I11: 0.00013181552 | J11: 8.6230424e-05 | N11: 75% | O11: 0.01 | P11: 1e-05 | Q11: 0 | R11: 0 | S11: 0 | T11: 0.4 | U11: 0
C12: max | D12: 0.058823529 | E12: 0.32051282 | F12: 0 | G12: 0 | H12: 0.02354049 | I12: 100 | J12: 0.09310987 | N12: max | O12: 0.05 | P12: 5e-05 | Q12: 0 | R12: 0 | S12: 0 | T12: 7 | U12: 1
A13: Data
A14: Percent Error = Absolute value of [(Difference) / (4p2\inferno.PRN)] x 100% | L14: Difference = (4p2\inferno4p2.out) - (4p2\inferno.PRN) | W14: 4p2\inferno4p2.out | AH14: 4p2\inferno.PRN
A15: Time | B15: Segment | C15: Sub | D15: AirTemp | E15: Humidity | F15: Sensible | G15: Latent | H15: WallTemp | I15: WallConvection | J15: WallRadiation | L15: Time | M15: Segment | N15: Sub | O15: AirTemp | P15: Humidity | Q15: Sensible | R15: Latent | S15: WallTemp | T15: WallConvection | U15: WallRadiation | W15: Time | X15: Segment | Y15: Sub | Z15: AirTemp | AA15: Humidity | AB15: Sensible | AC15: Latent | AD15: WallTemp | AE15: WallConvection | AF15: WallRadiation | AH15: Time | AI15: Segment | AJ15: Sub | AK15: AirTemp | AL15: Humidity | AM15: Sensible | AN15: Latent | AO15: WallTemp | AP15: WallConvection | AQ15: WallRadiation
A16: 0 | B16: 1 | C16: 1 | D16: 0 | E16: 0 | L16: 0 | M16: 1 | N16: 1 | O16: 0 | P16: 0 | Q16: 0 | R16: 0 | W16: 0 | X16: 1 | Y16: 1 | Z16: 85 | AA16: 0.01551 | AB16: 0 | AC16: 0 | AH16: 0 | AI16: 1 | AJ16: 1 | AK16: 85 | AL16: 0.01551 | AM16: 0 | AN16: 0
A17: 0 | B17: 1 | C17: 2 | D17: 0 | E17: 0 | L17: 0 | M17: 1 | N17: 2 | O17: 0 | P17: 0 | Q17: 0 | R17: 0 | W17: 0 | X17: 1 | Y17: 2 | Z17: 85 | AA17: 0.01551 | AB17: 0 | AC17: 0 | AH17: 0 | AI17: 1 | AJ17: 2 | AK17: 85 | AL17: 0.01551 | AM17: 0 | AN17: 0
A18: 0 | B18: 1 | C18: 3 | D18: 0 | E18: 0 | L18: 0 | M18: 1 | N18: 3 | O18: 0 | P18: 0 | Q18: 0 | R18: 0 | W18: 0 | X18: 1 | Y18: 3 | Z18: 85 | AA18: 0.01551 | AB18: 0 | AC18: 0 | AH18: 0 | AI18: 1 | AJ18: 3 | AK18: 85 | AL18: 0.01551 | AM18: 0 | AN18: 0
A19: 0 | B19: 1 | C19: 4 | D19: 0 | E19: 0 | L19: 0 | M19: 1 | N19: 4 | O19: 0 | P19: 0 | Q19: 0 | R19: 0 | W19: 0 | X19: 1 | Y19: 4 | Z19: 85 | AA19: 0.01551 | AB19: 0 | AC19: 0 | AH19: 0 | AI19: 1 | AJ19: 4 | AK19: 85 | AL19: 0.01551 | AM19: 0 | AN19: 0
A20: 0 | B20: 1 | C20: 5 | D20: 0 | E20: 0 | L20: 0 | M20: 1 | N20: 5 | O20: 0 | P20: 0 | Q20: 0 | R20: 0 | W20: 0 | X20: 1 | Y20: 5 | Z20: 85 | AA20: 0.01551 | AB20: 0 | AC20: 0 | AH20: 0 | AI20: 1 | AJ20: 5 | AK20: 85 | AL20: 0.01551 | AM20: 0 | AN20: 0
A21: 0 | B21: 1 | C21: 6 | D21: 0 | E21: 0 | L21: 0 | M21: 1 | N21: 6 | O21: 0 | P21: 0 | Q21: 0 | R21: 0 | W21: 0 | X21: 1 | Y21: 6 | Z21: 85 | AA21: 0.01551 | AB21: 0 | AC21: 0 | AH21: 0 | AI21: 1 | AJ21: 6 | AK21: 85 | AL21: 0.01551 | AM21: 0 | AN21: 0
A22: 0 | B22: 1 | C22: 7 | D22: 0 | E22: 0 | L22: 0 | M22: 1 | N22: 7 | O22: 0 | P22: 0 | Q22: 0 | R22: 0 | W22: 0 | X22: 1 | Y22: 7 | Z22: 85 | AA22: 0.01551 | AB22: 0 | AC22: 0 | AH22: 0 | AI22: 1 | AJ22: 7 | AK22: 85 | AL22: 0.01551 | AM22: 0 | AN22: 0
A23: 0 | B23: 1 | C23: 8 | D23: 0 | E23: 0 | L23: 0 | M23: 1 | N23: 8 | O23: 0 | P23: 0 | Q23: 0 | R23: 0 | W23: 0 | X23: 1 | Y23: 8 | Z23: 85 | AA23: 0.01551 | AB23: 0 | AC23: 0 | AH23: 0 | AI23: 1 | AJ23: 8 | AK23: 85 | AL23: 0.01551 | AM23: 0 | AN23: 0
A24: 0 | B24: 1 | C24: 9 | D24: 0 | E24: 0 | L24: 0 | M24: 1 | N24: 9 | O24: 0 | P24: 0 | Q24: 0 | R24: 0 | W24: 0 | X24: 1 | Y24: 9 | Z24: 85 | AA24: 0.01551 | AB24: 0 | AC24: 0 | AH24: 0 | AI24: 1 | AJ24: 9 | AK24: 85 | AL24: 0.01551 | AM24: 0 | AN24: 0
A25: 0 | B25: 1 | C25: 10 | D25: 0 | E25: 0 | L25: 0 | M25: 1 | N25: 10 | O25: 0 | P25: 0 | Q25: 0 | R25: 0 | W25: 0 | X25: 1 | Y25: 10 | Z25: 85 | AA25: 0.01551 | AB25: 0 | AC25: 0 | AH25: 0 | AI25: 1 | AJ25: 10 | AK25: 85 | AL25: 0.01551 | AM25: 0 | AN25: 0
A26: 0 | B26: 2 | C26: 1 | D26: 0 | E26: 0 | H26: 0 | L26: 0 | M26: 2 | N26: 1 | O26: 0 | P26: 0 | Q26: 0 | R26: 0 | S26: 0 | T26: 0 | U26: 0 | W26: 0 | X26: 2 | Y26: 1 | Z26: 85 | AA26: 0.01551 | AB26: 0 | AC26: 0 | AD26: 85 | AE26: 0 | AF26: 0 | AH26: 0 | AI26: 2 | AJ26: 1 | AK26: 85 | AL26: 0.01551 | AM26: 0 | AN26: 0 | AO26: 85 | AP26: 0 | AQ26: 0
A27: 0 | B27: 2 | C27: 2 | D27: 0 | E27: 0 | H27: 0 | L27: 0 | M27: 2 | N27: 2 | O27: 0 | P27: 0 | Q27: 0 | R27: 0 | S27: 0 | T27: 0 | U27: 0 | W27: 0 | X27: 2 | Y27: 2 | Z27: 85 | AA27: 0.01551 | AB27: 0 | AC27: 0 | AD27: 85 | AE27: 0 | AF27: 0 | AH27: 0 | AI27: 2 | AJ27: 2 | AK27: 85 | AL27: 0.01551 | AM27: 0 | AN27: 0 | AO27: 85 | AP27: 0 | AQ27: 0
A28: 0 | B28: 3 | C28: 1 | D28: 0 | E28: 0 | H28: 0 | L28: 0 | M28: 3 | N28: 1 | O28: 0 | P28: 0 | Q28: 0 | R28: 0 | S28: 0 | T28: 0 | U28: 0 | W28: 0 | X28: 3 | Y28: 1 | Z28: 85 | AA28: 0.01551 | AB28: 0 | AC28: 0 | AD28: 85 | AE28: 0 | AF28: 0 | AH28: 0 | AI28: 3 | AJ28: 1 | AK28: 85 | AL28: 0.01551 | AM28: 0 | AN28: 0 | AO28: 85 | AP28: 0 | AQ28: 0
A29: 0 | B29: 3 | C29: 2 | D29: 0 | E29: 0 | H29: 0 | L29: 0 | M29: 3 | N29: 2 | O29: 0 | P29: 0 | Q29: 0 | R29: 0 | S29: 0 | T29: 0 | U29: 0 | W29: 0 | X29: 3 | Y29: 2 | Z29: 85 | AA29: 0.01551 | AB29: 0 | AC29: 0 | AD29: 85 | AE29: 0 | AF29: 0 | AH29: 0 | AI29: 3 | AJ29: 2 | AK29: 85 | AL29: 0.01551 | AM29: 0 | AN29: 0 | AO29: 85 | AP29: 0 | AQ29: 0
A30: 0 | B30: 3 | C30: 3 | D30: 0 | E30: 0 | H30: 0 | L30: 0 | M30: 3 | N30: 3 | O30: 0 | P30: 0 | Q30: 0 | R30: 0 | S30: 0 | T30: 0 | U30: 0 | W30: 0 | X30: 3 | Y30: 3 | Z30: 85 | AA30: 0.01551 | AB30: 0 | AC30: 0 | AD30: 85 | AE30: 0 | AF30: 0 | AH30: 0 | AI30: 3 | AJ30: 3 | AK30: 85 | AL30: 0.01551 | AM30: 0 | AN30: 0 | AO30: 85 | AP30: 0 | AQ30: 0
A31: 0 | B31: 3 | C31: 4 | D31: 0 | E31: 0 | H31: 0 | L31: 0 | M31: 3 | N31: 4 | O31: 0 | P31: 0 | Q31: 0 | R31: 0 | S31: 0 | T31: 0 | U31: 0 | W31: 0 | X31: 3 | Y31: 4 | Z31: 85 | AA31: 0.01551 | AB31: 0 | AC31: 0 | AD31: 85 | AE31: 0 | AF31: 0 | AH31: 0 | AI31: 3 | AJ31: 4 | AK31: 85 | AL31: 0.01551 | AM31: 0 | AN31: 0 | AO31: 85 | AP31: 0 | AQ31: 0
A32: 0 | B32: 3 | C32: 5 | D32: 0 | E32: 0 | H32: 0 | L32: 0 | M32: 3 | N32: 5 | O32: 0 | P32: 0 | Q32: 0 | R32: 0 | S32: 0 | T32: 0 | U32: 0 | W32: 0 | X32: 3 | Y32: 5 | Z32: 85 | AA32: 0.01551 | AB32: 0 | AC32: 0 | AD32: 85 | AE32: 0 | AF32: 0 | AH32: 0 | AI32: 3 | AJ32: 5 | AK32: 85 | AL32: 0.01551 | AM32: 0 | AN32: 0 | AO32: 85 | AP32: 0 | AQ32: 0
A33: 0 | B33: 3 | C33: 6 | D33: 0 | E33: 0 | H33: 0 | L33: 0 | M33: 3 | N33: 6 | O33: 0 | P33: 0 | Q33: 0 | R33: 0 | S33: 0 | T33: 0 | U33: 0 | W33: 0 | X33: 3 | Y33: 6 | Z33: 85 | AA33: 0.01551 | AB33: 0 | AC33: 0 | AD33: 85 | AE33: 0 | AF33: 0 | AH33: 0 | AI33: 3 | AJ33: 6 | AK33: 85 | AL33: 0.01551 | AM33: 0 | AN33: 0 | AO33: 85 | AP33: 0 | AQ33: 0
A34: 0 | B34: 3 | C34: 7 | D34: 0 | E34: 0 | H34: 0 | L34: 0 | M34: 3 | N34: 7 | O34: 0 | P34: 0 | Q34: 0 | R34: 0 | S34: 0 | T34: 0 | U34: 0 | W34: 0 | X34: 3 | Y34: 7 | Z34: 85 | AA34: 0.01551 | AB34: 0 | AC34: 0 | AD34: 85 | AE34: 0 | AF34: 0 | AH34: 0 | AI34: 3 | AJ34: 7 | AK34: 85 | AL34: 0.01551 | AM34: 0 | AN34: 0 | AO34: 85 | AP34: 0 | AQ34: 0
A35: 0 | B35: 3 | C35: 8 | D35: 0 | E35: 0 | H35: 0 | L35: 0 | M35: 3 | N35: 8 | O35: 0 | P35: 0 | Q35: 0 | R35: 0 | S35: 0 | T35: 0 | U35: 0 | W35: 0 | X35: 3 | Y35: 8 | Z35: 85 | AA35: 0.01551 | AB35: 0 | AC35: 0 | AD35: 85 | AE35: 0 | AF35: 0 | AH35: 0 | AI35: 3 | AJ35: 8 | AK35: 85 | AL35: 0.01551 | AM35: 0 | AN35: 0 | AO35: 85 | AP35: 0 | AQ35: 0
A36: 0 | B36: 3 | C36: 9 | D36: 0 | E36: 0 | F36: 0 | G36: 0 | H36: 0 | L36: 0 | M36: 3 | N36: 9 | O36: 0 | P36: 0 | Q36: 0 | R36: 0 | S36: 0 | T36: 0 | U36: 0 | W36: 0 | X36: 3 | Y36: 9 | Z36: 85 | AA36: 0.01551 | AB36: 31.3 | AC36: 4.5 | AD36: 85 | AE36: 0 | AF36: 0 | AH36: 0 | AI36: 3 | AJ36: 9 | AK36: 85 | AL36: 0.01551 | AM36: 31.3 | AN36: 4.5 | AO36: 85 | AP36: 0 | AQ36: 0
A37: 0 | B37: 3 | C37: 10 | D37: 0 | E37: 0 | F37: 0 | G37: 0 | H37: 0 | L37: 0 | M37: 3 | N37: 10 | O37: 0 | P37: 0 | Q37: 0 | R37: 0 | S37: 0 | T37: 0 | U37: 0 | W37: 0 | X37: 3 | Y37: 10 | Z37: 85 | AA37: 0.01551 | AB37: 35 | AC37: 5.1 | AD37: 85 | AE37: 0 | AF37: 0 | AH37: 0 | AI37: 3 | AJ37: 10 | AK37: 85 | AL37: 0.01551 | AM37: 35 | AN37: 5.1 | AO37: 85 | AP37: 0 | AQ37: 0
A38: 0 | B38: 3 | C38: 11 | D38: 0 | E38: 0 | F38: 0 | G38: 0 | H38: 0 | I38: 100 | J38: 0 | L38: 0 | M38: 3 | N38: 11 | O38: 0 | P38: 0 | Q38: 0 | R38: 0 | S38: 0 | T38: 0.1 | U38: 0 | W38: 0 | X38: 3 | Y38: 11 | Z38: 85 | AA38: 0.01551 | AB38: 13368.3 | AC38: 5.1 | AD38: 85 | AE38: 0 | AF38: 11993855 | AH38: 0 | AI38: 3 | AJ38: 11 | AK38: 85 | AL38: 0.01551 | AM38: 13368.3 | AN38: 5.1 | AO38: 85 | AP38: -0.1 | AQ38: 11993855
A39: 0 | B39: 3 | C39: 12 | D39: 0 | E39: 0 | F39: 0 | G39: 0 | H39: 0 | L39: 0 | M39: 3 | N39: 12 | O39: 0 | P39: 0 | Q39: 0 | R39: 0 | S39: 0 | T39: 0 | U39: 0 | W39: 0 | X39: 3 | Y39: 12 | Z39: 85 | AA39: 0.01551 | AB39: 35 | AC39: 5.1 | AD39: 85 | AE39: 0 | AF39: 0 | AH39: 0 | AI39: 3 | AJ39: 12 | AK39: 85 | AL39: 0.01551 | AM39: 35 | AN39: 5.1 | AO39: 85 | AP39: 0 | AQ39: 0
A40: 0 | B40: 3 | C40: 13 | D40: 0 | E40: 0 | F40: 0 | G40: 0 | H40: 0 | L40: 0 | M40: 3 | N40: 13 | O40: 0 | P40: 0 | Q40: 0 | R40: 0 | S40: 0 | T40: 0 | U40: 0 | W40: 0 | X40: 3 | Y40: 13 | Z40: 85 | AA40: 0.01551 | AB40: 35 | AC40: 5.1 | AD40: 85 | AE40: 0 | AF40: 0 | AH40: 0 | AI40: 3 | AJ40: 13 | AK40: 85 | AL40: 0.01551 | AM40: 35 | AN40: 5.1 | AO40: 85 | AP40: 0 | AQ40: 0
...

Sheet TRA
A1: Next-Vis Sheet: TRA
A2: Summary
A3: Percent Error = Absolute value of [(Difference) / (4p2\inferno.PRN)] x 100% | T3: Difference = (4p2\inferno4p2.out) - (4p2\inferno.PRN)
C4: RTE | D4: TYP | E4: Location | F4: Speed | G4: Accel | H4: Drag_KN | I4: Drag_COEFF | J4: Tractive | K4: M_Current | L4: L_Current | M4: FLY | N4: M_Eff | O4: G_Accel | P4: G_Decel | Q4: H_Gen | R4: H_Reject | V4: RTE | W4: TYP | X4: Location | Y4: Speed | Z4: Accel | AA4: Draf_KN | AB4: Draf_COEFF | AC4: Tractive | AD4: M_Current | AE4: L_Current | AF4: FLY | AG4: M_Eff | AH4: G_Accel | AI4: G_Decel | AJ4: H_Gen | AK4: H_Reject
B5: count | C5: 25 | D5: 25 | E5: 25 | F5: 0 | G5: 0 | H5: 24 | I5: 0 | J5: 0 | K5: 0 | L5: 0 | M5: 0 | N5: 0 | O5: 25 | P5: 25 | Q5: 25 | R5: 25 | U5: count | V5: 25 | W5: 25 | X5: 25 | Y5: 25 | Z5: 25 | AA5: 25 | AB5: 25 | AC5: 25 | AD5: 25 | AE5: 25 | AF5: 25 | AG5: 0 | AH5: 25 | AI5: 25 | AJ5: 25 | AK5: 25
B6: mean | C6: 0 | D6: 0 | E6: 0 | H6: 0 | O6: 0 | P6: 0 | Q6: 0 | R6: 0 | U6: mean | V6: 0 | W6: 0 | X6: 0 | Y6: 0 | Z6: 0 | AA6: 0 | AB6: 0 | AC6: 0 | AD6: 0 | AE6: 0 | AF6: 0 | AH6: 0 | AI6: 0 | AJ6: 0 | AK6: 0
B7: std | C7: 0 | D7: 0 | E7: 0 | H7: 0 | O7: 0 | P7: 0 | Q7: 0 | R7: 0 | U7: std | V7: 0 | W7: 0 | X7: 0 | Y7: 0 | Z7: 0 | AA7: 0 | AB7: 0 | AC7: 0 | AD7: 0 | AE7: 0 | AF7: 0 | AH7: 0 | AI7: 0 | AJ7: 0 | AK7: 0
B8: min | C8: 0 | D8: 0 | E8: 0 | H8: 0 | O8: 0 | P8: 0 | Q8: 0 | R8: 0 | U8: min | V8: 0 | W8: 0 | X8: 0 | Y8: 0 | Z8: 0 | AA8: 0 | AB8: 0 | AC8: 0 | AD8: 0 | AE8: 0 | AF8: 0 | AH8: 0 | AI8: 0 | AJ8: 0 | AK8: 0
B9: 25% | C9: 0 | D9: 0 | E9: 0 | H9: 0 | O9: 0 | P9: 0 | Q9: 0 | R9: 0 | U9: 25% | V9: 0 | W9: 0 | X9: 0 | Y9: 0 | Z9: 0 | AA9: 0 | AB9: 0 | AC9: 0 | AD9: 0 | AE9: 0 | AF9: 0 | AH9: 0 | AI9: 0 | AJ9: 0 | AK9: 0
B10: 50% | C10: 0 | D10: 0 | E10: 0 | H10: 0 | O10: 0 | P10: 0 | Q10: 0 | R10: 0 | U10: 50% | V10: 0 | W10: 0 | X10: 0 | Y10: 0 | Z10: 0 | AA10: 0 | AB10: 0 | AC10: 0 | AD10: 0 | AE10: 0 | AF10: 0 | AH10: 0 | AI10: 0 | AJ10: 0 | AK10: 0
B11: 75% | C11: 0 | D11: 0 | E11: 0 | H11: 0 | O11: 0 | P11: 0 | Q11: 0 | R11: 0 | U11: 75% | V11: 0 | W11: 0 | X11: 0 | Y11: 0 | Z11: 0 | AA11: 0 | AB11: 0 | AC11: 0 | AD11: 0 | AE11: 0 | AF11: 0 | AH11: 0 | AI11: 0 | AJ11: 0 | AK11: 0
B12: max | C12: 0 | D12: 0 | E12: 0 | H12: 0 | O12: 0 | P12: 0 | Q12: 0 | R12: 0 | U12: max | V12: 0 | W12: 0 | X12: 0 | Y12: 0 | Z12: 0 | AA12: 0 | AB12: 0 | AC12: 0 | AD12: 0 | AE12: 0 | AF12: 0 | AH12: 0 | AI12: 0 | AJ12: 0 | AK12: 0
A13: Data
A14: Percent Error = Absolute value of [(Difference) / (4p2\inferno.PRN)] x 100% | T14: Difference = (4p2\inferno4p2.out) - (4p2\inferno.PRN) | AM14: 4p2\inferno4p2.out | BF14: 4p2\inferno.PRN
A15: Time | B15: Number | C15: RTE | D15: TYP | E15: Location | F15: Speed | G15: Accel | H15: Drag_KN | I15: Drag_COEFF | J15: Tractive | K15: M_Current | L15: L_Current | M15: FLY | N15: M_Eff | O15: G_Accel | P15: G_Decel | Q15: H_Gen | R15: H_Reject | T15: Time | U15: Number | V15: RTE | W15: TYP | X15: Location | Y15: Speed | Z15: Accel | AA15: Draf_KN | AB15: Draf_COEFF | AC15: Tractive | AD15: M_Current | AE15: L_Current | AF15: FLY | AG15: M_Eff | AH15: G_Accel | AI15: G_Decel | AJ15: H_Gen | AK15: H_Reject | AM15: Time | AN15: Number | AO15: RTE | AP15: TYP | AQ15: Location | AR15: Speed | AS15: Accel | AT15: Draf_KN | AU15: Draf_COEFF | AV15: Tractive | AW15: M_Current | AX15: L_Current | AY15: FLY | AZ15: M_Eff | BA15: G_Accel | BB15: G_Decel | BC15: H_Gen | BD15: H_Reject | BF15: Time | BG15: Number | BH15: RTE | BI15: TYP | BJ15: Location | BK15: Speed | BL15: Accel | BM15: Draf_KN | BN15: Draf_COEFF | BO15: Tractive | BP15: M_Current | BQ15: L_Current | BR15: FLY | BS15: M_Eff | BT15: G_Accel | BU15: G_Decel | BV15: H_Gen | BW15: H_Reject
A16: 0 | B16: 1 | C16: 0 | D16: 0 | E16: 0 | O16: 0 | P16: 0 | Q16: 0 | R16: 0 | T16: 0 | U16: 1 | V16: 0 | W16: 0 | X16: 0 | Y16: 0 | Z16: 0 | AA16: 0 | AB16: 0 | AC16: 0 | AD16: 0 | AE16: 0 | AF16: 0 | AH16: 0 | AI16: 0 | AJ16: 0 | AK16: 0 | AM16: 0 | AN16: 1 | AO16: 1 | AP16: 1 | AQ16: 4499 | AR16: 0 | AS16: 0 | AT16: 0 | AU16: 0 | AV16: 0 | AW16: 0 | AX16: 0 | AY16: 0 | BA16: 85 | BB16: 1200 | BC16: 0.49 | BD16: 0.49 | BF16: 0 | BG16: 1 | BH16: 1 | BI16: 1 | BJ16: 4499 | BK16: 0 | BL16: 0 | BM16: 0 | BN16: 0 | BO16: 0 | BP16: 0 | BQ16: 0 | BR16: 0 | BT16: 85 | BU16: 1200 | BV16: 0.49 | BW16: 0.49
A17: 10 | B17: 1 | C17: 0 | D17: 0 | E17: 0 | H17: 0 | O17: 0 | P17: 0 | Q17: 0 | R17: 0 | T17: 10 | U17: 1 | V17: 0 | W17: 0 | X17: 0 | Y17: 0 | Z17: 0 | AA17: 0 | AB17: 0 | AC17: 0 | AD17: 0 | AE17: 0 | AF17: 0 | AH17: 0 | AI17: 0 | AJ17: 0 | AK17: 0 | AM17: 10 | AN17: 1 | AO17: 1 | AP17: 1 | AQ17: 4499 | AR17: 0 | AS17: 0 | AT17: 402 | AU17: 0 | AV17: 0 | AW17: 0 | AX17: 0 | AY17: 0 | BA17: 85 | BB17: 1152.5 | BC17: 0.49 | BD17: 1.687 | BF17: 10 | BG17: 1 | BH17: 1 | BI17: 1 | BJ17: 4499 | BK17: 0 | BL17: 0 | BM17: 402 | BN17: 0 | BO17: 0 | BP17: 0 | BQ17: 0 | BR17: 0 | BT17: 85 | BU17: 1152.5 | BV17: 0.49 | BW17: 1.687
A18: 20 | B18: 1 | C18: 0 | D18: 0 | E18: 0 | H18: 0 | O18: 0 | P18: 0 | Q18: 0 | R18: 0 | T18: 20 | U18: 1 | V18: 0 | W18: 0 | X18: 0 | Y18: 0 | Z18: 0 | AA18: 0 | AB18: 0 | AC18: 0 | AD18: 0 | AE18: 0 | AF18: 0 | AH18: 0 | AI18: 0 | AJ18: 0 | AK18: 0 | AM18: 20 | AN18: 1 | AO18: 1 | AP18: 1 | AQ18: 4499 | AR18: 0 | AS18: 0 | AT18: 237 | AU18: 0 | AV18: 0 | AW18: 0 | AX18: 0 | AY18: 0 | BA18: 85 | BB18: 1102.8 | BC18: 0.49 | BD18: 1.595 | BF18: 20 | BG18: 1 | BH18: 1 | BI18: 1 | BJ18: 4499 | BK18: 0 | BL18: 0 | BM18: 237 | BN18: 0 | BO18: 0 | BP18: 0 | BQ18: 0 | BR18: 0 | BT18: 85 | BU18: 1102.8 | BV18: 0.49 | BW18: 1.595
A19: 30 | B19: 1 | C19: 0 | D19: 0 | E19: 0 | H19: 0 | O19: 0 | P19: 0 | Q19: 0 | R19: 0 | T19: 30 | U19: 1 | V19: 0 | W19: 0 | X19: 0 | Y19: 0 | Z19: 0 | AA19: 0 | AB19: 0 | AC19: 0 | AD19: 0 | AE19: 0 | AF19: 0 | AH19: 0 | AI19: 0 | AJ19: 0 | AK19: 0 | AM19: 30 | AN19: 1 | AO19: 1 | AP19: 1 | AQ19: 4499 | AR19: 0 | AS19: 0 | AT19: 200 | AU19: 0 | AV19: 0 | AW19: 0 | AX19: 0 | AY19: 0 | BA19: 85 | BB19: 1059.2 | BC19: 0.49 | BD19: 1.463 | BF19: 30 | BG19: 1 | BH19: 1 | BI19: 1 | BJ19: 4499 | BK19: 0 | BL19: 0 | BM19: 200 | BN19: 0 | BO19: 0 | BP19: 0 | BQ19: 0 | BR19: 0 | BT19: 85 | BU19: 1059.2 | BV19: 0.49 | BW19: 1.463
A20: 40 | B20: 1 | C20: 0 | D20: 0 | E20: 0 | H20: 0 | O20: 0 | P20: 0 | Q20: 0 | R20: 0 | T20: 40 | U20: 1 | V20: 0 | W20: 0 | X20: 0 | Y20: 0 | Z20: 0 | AA20: 0 | AB20: 0 | AC20: 0 | AD20: 0 | AE20: 0 | AF20: 0 | AH20: 0 | AI20: 0 | AJ20: 0 | AK20: 0 | AM20: 40 | AN20: 1 | AO20: 1 | AP20: 1 | AQ20: 4499 | AR20: 0 | AS20: 0 | AT20: 182 | AU20: 0 | AV20: 0 | AW20: 0 | AX20: 0 | AY20: 0 | BA20: 85 | BB20: 1020.3 | BC20: 0.49 | BD20: 1.367 | BF20: 40 | BG20: 1 | BH20: 1 | BI20: 1 | BJ20: 4499 | BK20: 0 | BL20: 0 | BM20: 182 | BN20: 0 | BO20: 0 | BP20: 0 | BQ20: 0 | BR20: 0 | BT20: 85 | BU20: 1020.3 | BV20: 0.49 | BW20: 1.367
A21: 50 | B21: 1 | C21: 0 | D21: 0 | E21: 0 | H21: 0 | O21: 0 | P21: 0 | Q21: 0 | R21: 0 | T21: 50 | U21: 1 | V21: 0 | W21: 0 | X21: 0 | Y21: 0 | Z21: 0 | AA21: 0 | AB21: 0 | AC21: 0 | AD21: 0 | AE21: 0 | AF21: 0 | AH21: 0 | AI21: 0 | AJ21: 0 | AK21: 0 | AM21: 50 | AN21: 1 | AO21: 1 | AP21: 1 | AQ21: 4499 | AR21: 0 | AS21: 0 | AT21: 172 | AU21: 0 | AV21: 0 | AW21: 0 | AX21: 0 | AY21: 0 | BA21: 85 | BB21: 984.9 | BC21: 0.49 | BD21: 1.293 | BF21: 50 | BG21: 1 | BH21: 1 | BI21: 1 | BJ21: 4499 | BK21: 0 | BL21: 0 | BM21: 172 | BN21: 0 | BO21: 0 | BP21: 0 | BQ21: 0 | BR21: 0 | BT21: 85 | BU21: 984.9 | BV21: 0.49 | BW21: 1.293
A22: 60 | B22: 1 | C22: 0 | D22: 0 | E22: 0 | H22: 0 | O22: 0 | P22: 0 | Q22: 0 | R22: 0 | T22: 60 | U22: 1 | V22: 0 | W22: 0 | X22: 0 | Y22: 0 | Z22: 0 | AA22: 0 | AB22: 0 | AC22: 0 | AD22: 0 | AE22: 0 | AF22: 0 | AH22: 0 | AI22: 0 | AJ22: 0 | AK22: 0 | AM22: 60 | AN22: 1 | AO22: 1 | AP22: 1 | AQ22: 4499 | AR22: 0 | AS22: 0 | AT22: 166 | AU22: 0 | AV22: 0 | AW22: 0 | AX22: 0 | AY22: 0 | BA22: 85 | BB22: 952.3 | BC22: 0.49 | BD22: 1.233 | BF22: 60 | BG22: 1 | BH22: 1 | BI22: 1 | BJ22: 4499 | BK22: 0 | BL22: 0 | BM22: 166 | BN22: 0 | BO22: 0 | BP22: 0 | BQ22: 0 | BR22: 0 | BT22: 85 | BU22: 952.3 | BV22: 0.49 | BW22: 1.233
A23: 70 | B23: 1 | C23: 0 | D23: 0 | E23: 0 | H23: 0 | O23: 0 | P23: 0 | Q23: 0 | R23: 0 | T23: 70 | U23: 1 | V23: 0 | W23: 0 | X23: 0 | Y23: 0 | Z23: 0 | AA23: 0 | AB23: 0 | AC23: 0 | AD23: 0 | AE23: 0 | AF23: 0 | AH23: 0 | AI23: 0 | AJ23: 0 | AK23: 0 | AM23: 70 | AN23: 1 | AO23: 1 | AP23: 1 | AQ23: 4499 | AR23: 0 | AS23: 0 | AT23: 161 | AU23: 0 | AV23: 0 | AW23: 0 | AX23: 0 | AY23: 0 | BA23: 85 | BB23: 922 | BC23: 0.49 | BD23: 1.182 | BF23: 70 | BG23: 1 | BH23: 1 | BI23: 1 | BJ23: 4499 | BK23: 0 | BL23: 0 | BM23: 161 | BN23: 0 | BO23: 0 | BP23: 0 | BQ23: 0 | BR23: 0 | BT23: 85 | BU23: 922 | BV23: 0.49 | BW23: 1.182
A24: 80 | B24: 1 | C24: 0 | D24: 0 | E24: 0 | H24: 0 | O24: 0 | P24: 0 | Q24: 0 | R24: 0 | T24: 80 | U24: 1 | V24: 0 | W24: 0 | X24: 0 | Y24: 0 | Z24: 0 | AA24: 0 | AB24: 0 | AC24: 0 | AD24: 0 | AE24: 0 | AF24: 0 | AH24: 0 | AI24: 0 | AJ24: 0 | AK24: 0 | AM24: 80 | AN24: 1 | AO24: 1 | AP24: 1 | AQ24: 4499 | AR24: 0 | AS24: 0 | AT24: 157 | AU24: 0 | AV24: 0 | AW24: 0 | AX24: 0 | AY24: 0 | BA24: 85 | BB24: 893.8 | BC24: 0.49 | BD24: 1.136 | BF24: 80 | BG24: 1 | BH24: 1 | BI24: 1 | BJ24: 4499 | BK24: 0 | BL24: 0 | BM24: 157 | BN24: 0 | BO24: 0 | BP24: 0 | BQ24: 0 | BR24: 0 | BT24: 85 | BU24: 893.8 | BV24: 0.49 | BW24: 1.136
A25: 90 | B25: 1 | C25: 0 | D25: 0 | E25: 0 | H25: 0 | O25: 0 | P25: 0 | Q25: 0 | R25: 0 | T25: 90 | U25: 1 | V25: 0 | W25: 0 | X25: 0 | Y25: 0 | Z25: 0 | AA25: 0 | AB25: 0 | AC25: 0 | AD25: 0 | AE25: 0 | AF25: 0 | AH25: 0 | AI25: 0 | AJ25: 0 | AK25: 0 | AM25: 90 | AN25: 1 | AO25: 1 | AP25: 1 | AQ25: 4499 | AR25: 0 | AS25: 0 | AT25: 153 | AU25: 0 | AV25: 0 | AW25: 0 | AX25: 0 | AY25: 0 | BA25: 85 | BB25: 867.3 | BC25: 0.49 | BD25: 1.096 | BF25: 90 | BG25: 1 | BH25: 1 | BI25: 1 | BJ25: 4499 | BK25: 0 | BL25: 0 | BM25: 153 | BN25: 0 | BO25: 0 | BP25: 0 | BQ25: 0 | BR25: 0 | BT25: 85 | BU25: 867.3 | BV25: 0.49 | BW25: 1.096
A26: 100 | B26: 1 | C26: 0 | D26: 0 | E26: 0 | H26: 0 | O26: 0 | P26: 0 | Q26: 0 | R26: 0 | T26: 100 | U26: 1 | V26: 0 | W26: 0 | X26: 0 | Y26: 0 | Z26: 0 | AA26: 0 | AB26: 0 | AC26: 0 | AD26: 0 | AE26: 0 | AF26: 0 | AH26: 0 | AI26: 0 | AJ26: 0 | AK26: 0 | AM26: 100 | AN26: 1 | AO26: 1 | AP26: 1 | AQ26: 4499 | AR26: 0 | AS26: 0 | AT26: 149 | AU26: 0 | AV26: 0 | AW26: 0 | AX26: 0 | AY26: 0 | BA26: 85 | BB26: 842.5 | BC26: 0.49 | BD26: 1.059 | BF26: 100 | BG26: 1 | BH26: 1 | BI26: 1 | BJ26: 4499 | BK26: 0 | BL26: 0 | BM26: 149 | BN26: 0 | BO26: 0 | BP26: 0 | BQ26: 0 | BR26: 0 | BT26: 85 | BU26: 842.5 | BV26: 0.49 | BW26: 1.059
A27: 120 | B27: 1 | C27: 0 | D27: 0 | E27: 0 | H27: 0 | O27: 0 | P27: 0 | Q27: 0 | R27: 0 | T27: 120 | U27: 1 | V27: 0 | W27: 0 | X27: 0 | Y27: 0 | Z27: 0 | AA27: 0 | AB27: 0 | AC27: 0 | AD27: 0 | AE27: 0 | AF27: 0 | AH27: 0 | AI27: 0 | AJ27: 0 | AK27: 0 | AM27: 120 | AN27: 1 | AO27: 1 | AP27: 1 | AQ27: 4499 | AR27: 0 | AS27: 0 | AT27: 143 | AU27: 0 | AV27: 0 | AW27: 0 | AX27: 0 | AY27: 0 | BA27: 85 | BB27: 797.1 | BC27: 0.49 | BD27: 0.996 | BF27: 120 | BG27: 1 | BH27: 1 | BI27: 1 | BJ27: 4499 | BK27: 0 | BL27: 0 | BM27: 143 | BN27: 0 | BO27: 0 | BP27: 0 | BQ27: 0 | BR27: 0 | BT27: 85 | BU27: 797.1 | BV27: 0.49 | BW27: 0.996
A28: 140 | B28: 1 | C28: 0 | D28: 0 | E28: 0 | H28: 0 | O28: 0 | P28: 0 | Q28: 0 | R28: 0 | T28: 140 | U28: 1 | V28: 0 | W28: 0 | X28: 0 | Y28: 0 | Z28: 0 | AA28: 0 | AB28: 0 | AC28: 0 | AD28: 0 | AE28: 0 | AF28: 0 | AH28: 0 | AI28: 0 | AJ28: 0 | AK28: 0 | AM28: 140 | AN28: 1 | AO28: 1 | AP28: 1 | AQ28: 4499 | AR28: 0 | AS28: 0 | AT28: 139 | AU28: 0 | AV28: 0 | AW28: 0 | AX28: 0 | AY28: 0 | BA28: 85 | BB28: 756.7 | BC28: 0.49 | BD28: 0.942 | BF28: 140 | BG28: 1 | BH28: 1 | BI28: 1 | BJ28: 4499 | BK28: 0 | BL28: 0 | BM28: 139 | BN28: 0 | BO28: 0 | BP28: 0 | BQ28: 0 | BR28: 0 | BT28: 85 | BU28: 756.7 | BV28: 0.49 | BW28: 0.942
... A40: 500 | B40: 1 | C40: 0 | D40: 0 | E40: 0 | H40: 0 | O40: 0 | P40: 0 | Q40: 0 | R40: 0 | T40: 500 | U40: 1 | V40: 0 | W40: 0 | X40: 0 | Y40: 0 | Z40: 0 | AA40: 0 | AB40: 0 | AC40: 0 | AD40: 0 | AE40: 0 | AF40: 0 | AH40: 0 | AI40: 0 | AJ40: 0 | AK40: 0 | AM40: 500 | AN40: 1 | AO40: 1 | AP40: 1 | AQ40: 4499 | AR40: 0 | AS40: 0 | AT40: 123 | AU40: 0 | AV40: 0 | AW40: 0 | AX40: 0 | AY40: 0 | BA40: 85 | BB40: 414.4 | BC40: 0.49 | BD40: 0.591 | BF40: 500 | BG40: 1 | BH40: 1 | BI40: 1 | BJ40: 4499 | BK40: 0 | BL40: 0 | BM40: 123 | BN40: 0 | BO40: 0 | BP40: 0 | BQ40: 0 | BR40: 0 | BT40: 85 | BU40: 414.4 | BV40: 0.49 | BW40: 0.591
