Workbook

Sheet Summary
A1: Percent Error = Absolute value of [(Difference) / (4p2\normal.PRN)] x 100%
B3: Sheet | C3: SSA | E3: SST | I3: TRA | Y3: SEG | AO3: SUB | BL3: TES | BP3: HAS | BV3: ECS
B4: Column | C4: =SSA!C4 -> Airflow | D4: =SSA!D4 -> AirVel | E4: =SST!D4 -> AirTemp | F4: =SST!E4 -> Humidity | G4: =SST!F4 -> Sensible | H4: =SST!G4 -> Latent | I4: =TRA!C4 -> RTE | J4: =TRA!D4 -> TYP | K4: =TRA!E4 -> Location | L4: =TRA!F4 -> Speed | M4: =TRA!G4 -> Accel | N4: =TRA!H4 -> Drag_KN | O4: =TRA!I4 -> Drag_COEFF | P4: =TRA!J4 -> Tractive | ... X4: =TRA!R4 -> H_Reject | Y4: =SEG!V4 -> A_Max | Z4: =SEG!W4 -> A_Max_T | AA4: =SEG!X4 -> A_Min | AB4: =SEG!Y4 -> A_Min_T | AC4: =SEG!Z4 -> A_P | AD4: =SEG!AA4 -> A_N | AE4: =SEG!AB4 -> V_Max | AF4: =SEG!AC4 -> V_Max_T | ... AN4: =SEG!AK4 -> V_EP | AO4: =SUB!D4 -> T_Max | AP4: =SUB!E4 -> T_Max_T | AQ4: =SUB!F4 -> T_Min | AR4: =SUB!G4 -> T_Min_T | AS4: =SUB!H4 -> T_P | AT4: =SUB!I4 -> T_N | AU4: =SUB!J4 -> W_Max | AV4: =SUB!K4 -> W_Max_T | ... AY4: =SUB!N4 -> W_A | AZ4: =PER!D4 -> TAP_1 | BA4: =PER!E4 -> TAP_2 | BB4: =PER!F4 -> TAP_3 | BC4: =PER!G4 -> TAP_4 | BD4: =PER!H4 -> TAP_5 | BE4: =PER!I4 -> TAP_6 | BF4: =PER!J4 -> TA_1 | BG4: =PER!K4 -> TA_2 | ... BK4: =PER!O4 -> TA_6 | BL4: =TES!C4 -> ET | BM4: =TES!D4 -> EF | BN4: =TES!E4 -> EA | BO4: =TES!F4 -> ER | BP4: =HSA!E4 -> MWT | BQ4: =HSA!F4 -> EWT | BR4: =HSA!G4 -> MAT | BS4: =HSA!H4 -> EAT | BT4: =HSA!I4 -> MH | BU4: =HSA!J4 -> EH | BV4: TM_S | BW4: TM_L | BX4: SS_S | BY4: SS_L | BZ4: HS_S | CA4: A_S | CB4: A_L | CC4: EC_S | CD4: EC_L | CE4: TR_S | CF4: TR_L | CG4: TR_T
B5: =SSA!B5 -> count | C5: =SSA!C5 -> 288 | D5: =SSA!D5 -> 288 | E5: =SST!D5 -> 418 | F5: =SST!E5 -> 418 | G5: =SST!F5 -> 210 | H5: =SST!G5 -> 179 | I5: =TRA!C5 -> 41 | J5: =TRA!D5 -> 41 | K5: =TRA!E5 -> 41 | L5: =TRA!F5 -> 35 | M5: =TRA!G5 -> 32 | N5: =TRA!H5 -> 33 | O5: =TRA!I5 -> 33 | P5: =TRA!J5 -> 20 | ... X5: =TRA!R5 -> 41 | Y5: =SEG!V5 -> 72 | Z5: =SEG!W5 -> 72 | AA5: =SEG!X5 -> 72 | AB5: =SEG!Y5 -> 72 | AC5: =SEG!Z5 -> 72 | AD5: =SEG!AA5 -> 72 | AE5: =SEG!AB5 -> 72 | AF5: =SEG!AC5 -> 72 | ... AN5: =SEG!AK5 -> 72 | AO5: =SUB!D5 -> 136 | AP5: =SUB!E5 -> 136 | AQ5: =SUB!F5 -> 136 | AR5: =SUB!G5 -> 136 | AS5: =SUB!H5 -> 96 | AT5: =SUB!I5 -> 116 | AU5: =SUB!J5 -> 136 | AV5: =SUB!K5 -> 136 | ... AY5: =SUB!N5 -> 136 | AZ5: =PER!D5 -> 40 | BA5: =PER!E5 -> 40 | BB5: =PER!F5 -> 40 | BC5: =PER!G5 -> 25 | BD5: =PER!H5 -> 15 | BE5: =PER!I5 -> 12 | BF5: =PER!J5 -> 40 | BG5: =PER!K5 -> 40 | ... BK5: =PER!O5 -> 40 | BL5: =TES!C5 -> 20 | BM5: =TES!D5 -> 12 | BN5: =TES!E5 -> 24 | BO5: =TES!F5 -> 12 | BP5: =HSA!E5 -> 72 | BQ5: =HSA!F5 -> 72 | BR5: =HSA!G5 -> 72 | BS5: =HSA!H5 -> 72 | BT5: =HSA!I5 -> 72 | BU5: =HSA!J5 -> 72 | BV5: 30 | BW5: 19 | BX5: 30 | BY5: 18 | BZ5: 30 | CA5: 30 | CB5: 30 | CC5: 20 | CD5: 20 | CE5: 30 | CF5: 30 | CG5: 30
B6: Mean | C6: =SSA!C6 -> 0.00036919344 | D6: =SSA!D6 -> 0.00011838846 | E6: =SST!D6 -> 0.01279533 | F6: =SST!E6 -> 0.058289486 | G6: =SST!F6 -> 0 | H6: =SST!G6 -> 0.00040133565 | I6: =TRA!C6 -> 0 | J6: =TRA!D6 -> 0 | K6: =TRA!E6 -> 0 | L6: =TRA!F6 -> 0 | M6: =TRA!G6 -> 0 | N6: =TRA!H6 -> 0 | O6: =TRA!I6 -> 0 | P6: =TRA!J6 -> 0 | ... X6: =TRA!R6 -> 0.0015485869 | Y6: =SEG!V6 -> 5.5555556e-05 | Z6: =SEG!W6 -> 0 | AA6: =SEG!X6 -> 0.00022222222 | AB6: =SEG!Y6 -> 0 | AC6: =SEG!Z6 -> 8.3333333e-05 | AD6: =SEG!AA6 -> 5.5555556e-05 | AE6: =SEG!AB6 -> 0 | AF6: =SEG!AC6 -> 0 | ... AN6: =SEG!AK6 -> 0 | AO6: =SUB!D6 -> 0 | AP6: =SUB!E6 -> 0.0004543761 | AQ6: =SUB!F6 -> 0 | AR6: =SUB!G6 -> 0.0071124842 | AS6: =SUB!H6 -> 0 | AT6: =SUB!I6 -> 0 | AU6: =SUB!J6 -> 0 | AV6: =SUB!K6 -> 0.0091908434 | ... AY6: =SUB!N6 -> 0 | AZ6: =PER!D6 -> 0 | BA6: =PER!E6 -> 0 | BB6: =PER!F6 -> 0 | BC6: =PER!G6 -> 0 | BD6: =PER!H6 -> 0 | BE6: =PER!I6 -> 0 | BF6: =PER!J6 -> 0 | BG6: =PER!K6 -> 0 | ... BK6: =PER!O6 -> 0 | BL6: =TES!C6 -> 0 | BM6: =TES!D6 -> 0 | BN6: =TES!E6 -> 0 | BO6: =TES!F6 -> 0 | BP6: =HSA!E6 -> 0 | BQ6: =HSA!F6 -> 0 | BR6: =HSA!G6 -> 0 | BS6: =HSA!H6 -> 0 | BT6: =HSA!I6 -> 0 | BU6: =HSA!J6 -> 0 | BV6: 0.00010555917 | BW6: 5.2637221 | BX6: 5.5096419e-05 | BY6: 0 | BZ6: 0 | CA6: 0.0065489111 | CB6: 0.060351291 | CC6: 0.001882517 | CD6: 0.0025308158 | CE6: 0.0022340321 | CF6: 0.0020818705 | CG6: 0.0042988381
B7: =SSA!B7 -> std | C7: =SSA!C7 -> 0.0011293255 | D7: =SSA!D7 -> 0.0014579093 | E7: =SST!D7 -> 0.018097983 | F7: =SST!E7 -> 0.092496412 | G7: =SST!F7 -> 0 | H7: =SST!G7 -> 0.005369505 | I7: =TRA!C7 -> 0 | J7: =TRA!D7 -> 0 | K7: =TRA!E7 -> 0 | L7: =TRA!F7 -> 0 | M7: =TRA!G7 -> 0 | N7: =TRA!H7 -> 0 | O7: =TRA!I7 -> 0 | P7: =TRA!J7 -> 0 | ... X7: =TRA!R7 -> 0.0099157944 | Y7: =SEG!V7 -> 0.00028526681 | Z7: =SEG!W7 -> 0 | AA7: =SEG!X7 -> 0.00053660965 | AB7: =SEG!Y7 -> 0 | AC7: =SEG!Z7 -> 0.00032501354 | AD7: =SEG!AA7 -> 0.00023066889 | AE7: =SEG!AB7 -> 0 | AF7: =SEG!AC7 -> 0 | ... AN7: =SEG!AK7 -> 0 | AO7: =SUB!D7 -> 0 | AP7: =SUB!E7 -> 0.0052988903 | AQ7: =SUB!F7 -> 0 | AR7: =SUB!G7 -> 0.055463386 | AS7: =SUB!H7 -> 0 | AT7: =SUB!I7 -> 0 | AU7: =SUB!J7 -> 0 | AV7: =SUB!K7 -> 0.057993532 | ... AY7: =SUB!N7 -> 0 | AZ7: =PER!D7 -> 0 | BA7: =PER!E7 -> 0 | BB7: =PER!F7 -> 0 | BC7: =PER!G7 -> 0 | BD7: =PER!H7 -> 0 | BE7: =PER!I7 -> 0 | BF7: =PER!J7 -> 0 | BG7: =PER!K7 -> 0 | ... BK7: =PER!O7 -> 0 | BL7: =TES!C7 -> 0 | BM7: =TES!D7 -> 0 | BN7: =TES!E7 -> 0 | BO7: =TES!F7 -> 0 | BP7: =HSA!E7 -> 0 | BQ7: =HSA!F7 -> 0 | BR7: =HSA!G7 -> 0 | BS7: =HSA!H7 -> 0 | BT7: =HSA!I7 -> 0 | BU7: =HSA!J7 -> 0 | BV7: 0.00012366219 | BW7: 22.941437 | BX7: 0.00030177551 | BY7: 0 | BZ7: 0 | CA7: 0.011433685 | CB7: 0.31429021 | CC7: 0.003728484 | CD7: 0.00372746 | CE7: 0.0046333855 | CF7: 0.0031399214 | CG7: 0.01234051
B8: =SSA!B8 -> min | C8: =SSA!C8 -> 0 | D8: =SSA!D8 -> 0 | E8: =SST!D8 -> 0 | F8: =SST!E8 -> 0 | G8: =SST!F8 -> 0 | H8: =SST!G8 -> 0 | I8: =TRA!C8 -> 0 | J8: =TRA!D8 -> 0 | K8: =TRA!E8 -> 0 | L8: =TRA!F8 -> 0 | M8: =TRA!G8 -> 0 | N8: =TRA!H8 -> 0 | O8: =TRA!I8 -> 0 | P8: =TRA!J8 -> 0 | ... X8: =TRA!R8 -> 0 | Y8: =SEG!V8 -> -0.001 | Z8: =SEG!W8 -> 0 | AA8: =SEG!X8 -> -0.001 | AB8: =SEG!Y8 -> 0 | AC8: =SEG!Z8 -> -0.001 | AD8: =SEG!AA8 -> 0 | AE8: =SEG!AB8 -> 0 | AF8: =SEG!AC8 -> 0 | ... AN8: =SEG!AK8 -> 0 | AO8: =SUB!D8 -> 0 | AP8: =SUB!E8 -> 0 | AQ8: =SUB!F8 -> 0 | AR8: =SUB!G8 -> 0 | AS8: =SUB!H8 -> 0 | AT8: =SUB!I8 -> 0 | AU8: =SUB!J8 -> 0 | AV8: =SUB!K8 -> 0 | ... AY8: =SUB!N8 -> 0 | AZ8: =PER!D8 -> 0 | BA8: =PER!E8 -> 0 | BB8: =PER!F8 -> 0 | BC8: =PER!G8 -> 0 | BD8: =PER!H8 -> 0 | BE8: =PER!I8 -> 0 | BF8: =PER!J8 -> 0 | BG8: =PER!K8 -> 0 | ... BK8: =PER!O8 -> 0 | BL8: =TES!C8 -> 0 | BM8: =TES!D8 -> 0 | BN8: =TES!E8 -> 0 | BO8: =TES!F8 -> 0 | BP8: =HSA!E8 -> 0 | BQ8: =HSA!F8 -> 0 | BR8: =HSA!G8 -> 0 | BS8: =HSA!H8 -> 0 | BT8: =HSA!I8 -> 0 | BU8: =HSA!J8 -> 0 | BV8: 0 | BW8: 0 | BX8: 0 | BY8: 0 | BZ8: 0 | CA8: 0 | CB8: 0 | CC8: 0 | CD8: 0 | CE8: 0 | CF8: 0 | CG8: 0
B9: =SSA!B9 -> 25% | C9: =SSA!C9 -> 0 | D9: =SSA!D9 -> 0 | E9: =SST!D9 -> 0 | F9: =SST!E9 -> 0 | G9: =SST!F9 -> 0 | H9: =SST!G9 -> 0 | I9: =TRA!C9 -> 0 | J9: =TRA!D9 -> 0 | K9: =TRA!E9 -> 0 | L9: =TRA!F9 -> 0 | M9: =TRA!G9 -> 0 | N9: =TRA!H9 -> 0 | O9: =TRA!I9 -> 0 | P9: =TRA!J9 -> 0 | ... X9: =TRA!R9 -> 0 | Y9: =SEG!V9 -> 0 | Z9: =SEG!W9 -> 0 | AA9: =SEG!X9 -> 0 | AB9: =SEG!Y9 -> 0 | AC9: =SEG!Z9 -> 0 | AD9: =SEG!AA9 -> 0 | AE9: =SEG!AB9 -> 0 | AF9: =SEG!AC9 -> 0 | ... AN9: =SEG!AK9 -> 0 | AO9: =SUB!D9 -> 0 | AP9: =SUB!E9 -> 0 | AQ9: =SUB!F9 -> 0 | AR9: =SUB!G9 -> 0 | AS9: =SUB!H9 -> 0 | AT9: =SUB!I9 -> 0 | AU9: =SUB!J9 -> 0 | AV9: =SUB!K9 -> 0 | ... AY9: =SUB!N9 -> 0 | AZ9: =PER!D9 -> 0 | BA9: =PER!E9 -> 0 | BB9: =PER!F9 -> 0 | BC9: =PER!G9 -> 0 | BD9: =PER!H9 -> 0 | BE9: =PER!I9 -> 0 | BF9: =PER!J9 -> 0 | BG9: =PER!K9 -> 0 | ... BK9: =PER!O9 -> 0 | BL9: =TES!C9 -> 0 | BM9: =TES!D9 -> 0 | BN9: =TES!E9 -> 0 | BO9: =TES!F9 -> 0 | BP9: =HSA!E9 -> 0 | BQ9: =HSA!F9 -> 0 | BR9: =HSA!G9 -> 0 | BS9: =HSA!H9 -> 0 | BT9: =HSA!I9 -> 0 | BU9: =HSA!J9 -> 0 | BV9: 0 | BW9: 0 | BX9: 0 | BY9: 0 | BZ9: 0 | CA9: 0.00025477603 | CB9: 0.00046895924 | CC9: 3.7353072e-05 | CD9: 0.00058525513 | CE9: 0.00010724572 | CF9: 0.00051731801 | CG9: 0.00022455074
B10: =SSA!B10 -> 50% | C10: =SSA!C10 -> 6.1007583e-05 | D10: =SSA!D10 -> 0 | E10: =SST!D10 -> 0 | F10: =SST!E10 -> 0 | G10: =SST!F10 -> 0 | H10: =SST!G10 -> 0 | I10: =TRA!C10 -> 0 | J10: =TRA!D10 -> 0 | K10: =TRA!E10 -> 0 | L10: =TRA!F10 -> 0 | M10: =TRA!G10 -> 0 | N10: =TRA!H10 -> 0 | O10: =TRA!I10 -> 0 | P10: =TRA!J10 -> 0 | ... X10: =TRA!R10 -> 0 | Y10: =SEG!V10 -> 0 | Z10: =SEG!W10 -> 0 | AA10: =SEG!X10 -> 0 | AB10: =SEG!Y10 -> 0 | AC10: =SEG!Z10 -> 0 | AD10: =SEG!AA10 -> 0 | AE10: =SEG!AB10 -> 0 | AF10: =SEG!AC10 -> 0 | ... AN10: =SEG!AK10 -> 0 | AO10: =SUB!D10 -> 0 | AP10: =SUB!E10 -> 0 | AQ10: =SUB!F10 -> 0 | AR10: =SUB!G10 -> 0 | AS10: =SUB!H10 -> 0 | AT10: =SUB!I10 -> 0 | AU10: =SUB!J10 -> 0 | AV10: =SUB!K10 -> 0 | ... AY10: =SUB!N10 -> 0 | AZ10: =PER!D10 -> 0 | BA10: =PER!E10 -> 0 | BB10: =PER!F10 -> 0 | BC10: =PER!G10 -> 0 | BD10: =PER!H10 -> 0 | BE10: =PER!I10 -> 0 | BF10: =PER!J10 -> 0 | BG10: =PER!K10 -> 0 | ... BK10: =PER!O10 -> 0 | BL10: =TES!C10 -> 0 | BM10: =TES!D10 -> 0 | BN10: =TES!E10 -> 0 | BO10: =TES!F10 -> 0 | BP10: =HSA!E10 -> 0 | BQ10: =HSA!F10 -> 0 | BR10: =HSA!G10 -> 0 | BS10: =HSA!H10 -> 0 | BT10: =HSA!I10 -> 0 | BU10: =HSA!J10 -> 0 | BV10: 0 | BW10: 0 | BX10: 0 | BY10: 0 | BZ10: 0 | CA10: 0.0013680441 | CB10: 0.0010222936 | CC10: 0.00064907025 | CD10: 0.0010515979 | CE10: 0.0005799332 | CF10: 0.001012799 | CG10: 0.00069529761
B11: =SSA!B11 -> 75% | C11: =SSA!C11 -> 0.00026707333 | D11: =SSA!D11 -> 0 | E11: =SST!D11 -> 0.023337223 | F11: =SST!E11 -> 0.099009901 | G11: =SST!F11 -> 0 | H11: =SST!G11 -> 0 | I11: =TRA!C11 -> 0 | J11: =TRA!D11 -> 0 | K11: =TRA!E11 -> 0 | L11: =TRA!F11 -> 0 | M11: =TRA!G11 -> 0 | N11: =TRA!H11 -> 0 | O11: =TRA!I11 -> 0 | P11: =TRA!J11 -> 0 | ... X11: =TRA!R11 -> 0 | Y11: =SEG!V11 -> 0 | Z11: =SEG!W11 -> 0 | AA11: =SEG!X11 -> 0.00025 | AB11: =SEG!Y11 -> 0 | AC11: =SEG!Z11 -> 0 | AD11: =SEG!AA11 -> 0 | AE11: =SEG!AB11 -> 0 | AF11: =SEG!AC11 -> 0 | ... AN11: =SEG!AK11 -> 0 | AO11: =SUB!D11 -> 0 | AP11: =SUB!E11 -> 0 | AQ11: =SUB!F11 -> 0 | AR11: =SUB!G11 -> 0 | AS11: =SUB!H11 -> 0 | AT11: =SUB!I11 -> 0 | AU11: =SUB!J11 -> 0 | AV11: =SUB!K11 -> 0 | ... AY11: =SUB!N11 -> 0 | AZ11: =PER!D11 -> 0 | BA11: =PER!E11 -> 0 | BB11: =PER!F11 -> 0 | BC11: =PER!G11 -> 0 | BD11: =PER!H11 -> 0 | BE11: =PER!I11 -> 0 | BF11: =PER!J11 -> 0 | BG11: =PER!K11 -> 0 | ... BK11: =PER!O11 -> 0 | BL11: =TES!C11 -> 0 | BM11: =TES!D11 -> 0 | BN11: =TES!E11 -> 0 | BO11: =TES!F11 -> 0 | BP11: =HSA!E11 -> 0 | BQ11: =HSA!F11 -> 0 | BR11: =HSA!G11 -> 0 | BS11: =HSA!H11 -> 0 | BT11: =HSA!I11 -> 0 | BU11: =HSA!J11 -> 0 | BV11: 0.000230514 | BW11: 0 | BX11: 0 | BY11: 0 | BZ11: 0 | CA11: 0.0057599288 | CB11: 0.0025575268 | CC11: 0.0015616954 | CD11: 0.0028670778 | CE11: 0.0016239594 | CF11: 0.0023633621 | CG11: 0.0021513383
B12: Max | C12: =SSA!C12 -> 0.012537613 | D12: =SSA!D12 -> 0.021097046 | E12: =SST!D12 -> 0.06090134 | F12: =SST!E12 -> 0.47169811 | G12: =SST!F12 -> 0 | H12: =SST!G12 -> 0.07183908 | I12: =TRA!C12 -> 0 | J12: =TRA!D12 -> 0 | K12: =TRA!E12 -> 0 | L12: =TRA!F12 -> 0 | M12: =TRA!G12 -> 0 | N12: =TRA!H12 -> 0 | O12: =TRA!I12 -> 0 | P12: =TRA!J12 -> 0 | ... X12: =TRA!R12 -> 0.063492063 | Y12: =SEG!V12 -> 0.001 | Z12: =SEG!W12 -> 0 | AA12: =SEG!X12 -> 0.002 | AB12: =SEG!Y12 -> 0 | AC12: =SEG!Z12 -> 0.001 | AD12: =SEG!AA12 -> 0.001 | AE12: =SEG!AB12 -> 0 | AF12: =SEG!AC12 -> 0 | ... AN12: =SEG!AK12 -> 0 | AO12: =SUB!D12 -> 0 | AP12: =SUB!E12 -> 0.061795149 | AQ12: =SUB!F12 -> 0 | AR12: =SUB!G12 -> 0.55924502 | AS12: =SUB!H12 -> 0 | AT12: =SUB!I12 -> 0 | AU12: =SUB!J12 -> 0 | AV12: =SUB!K12 -> 0.55613486 | ... AY12: =SUB!N12 -> 0 | AZ12: =PER!D12 -> 0 | BA12: =PER!E12 -> 0 | BB12: =PER!F12 -> 0 | BC12: =PER!G12 -> 0 | BD12: =PER!H12 -> 0 | BE12: =PER!I12 -> 0 | BF12: =PER!J12 -> 0 | BG12: =PER!K12 -> 0 | ... BK12: =PER!O12 -> 0 | BL12: =TES!C12 -> 0 | BM12: =TES!D12 -> 0 | BN12: =TES!E12 -> 0 | BO12: =TES!F12 -> 0 | BP12: =HSA!E12 -> 0 | BQ12: =HSA!F12 -> 0 | BR12: =HSA!G12 -> 0 | BS12: =HSA!H12 -> 0 | BT12: =HSA!I12 -> 0 | BU12: =HSA!J12 -> 0 | BV12: 0.0002924618 | BW12: 100 | BX12: 0.0016528926 | BY12: 0 | BZ12: 0 | CA12: 0.045489007 | CB12: 1.7241379 | CC12: 0.015921032 | CD12: 0.013596193 | CE12: 0.02034588 | CF12: 0.013596193 | CG12: 0.057430007
A14: Percent Error = Absolute value of [(Difference) / (4p2\normal.PRN)] x 100%
A15: {=TRANSPOSE(B3:CG12)} -> Sheet | B15: Column | C15: count | D15: Mean | E15: std | F15: min | G15: 25% | H15: 50% | I15: 75% | J15: Max | K15: Description | L15: Unit
A16: SSA | B16: Airflow | C16: 288 | D16: 0.00036919344 | E16: 0.0011293255 | F16: 0 | G16: 0 | H16: 6.1007583e-05 | I16: 0.00026707333 | J16: 0.012537613 | K16: =VLOOKUP($B16,Legend!$B$2:$E$110,2,FALSE) -> Section Air Flow Rate | L16: =VLOOKUP($B16,Legend!$B$2:$E$110,4,FALSE) -> kCFM
A17: 0 | B17: AirVel | C17: 288 | D17: 0.00011838846 | E17: 0.0014579093 | F17: 0 | G17: 0 | H17: 0 | I17: 0 | J17: 0.021097046 | K17: =VLOOKUP(B17,Legend!$B$2:$E$110,2,FALSE) -> Bulk Air Velocity | L17: =VLOOKUP($B17,Legend!$B$2:$E$110,4,FALSE) -> FPM
A18: SST | B18: AirTemp | C18: 418 | D18: 0.01279533 | E18: 0.018097983 | F18: 0 | G18: 0 | H18: 0 | I18: 0.023337223 | J18: 0.06090134 | K18: =VLOOKUP(B18,Legend!$B$2:$E$110,2,FALSE) -> Air Dry-Bulb Temperature | L18: =VLOOKUP($B18,Legend!$B$2:$E$110,4,FALSE) -> °F
A19: 0 | B19: Humidity | C19: 418 | D19: 0.058289486 | E19: 0.092496412 | F19: 0 | G19: 0 | H19: 0 | I19: 0.099009901 | J19: 0.47169811 | K19: =VLOOKUP(B19,Legend!$B$2:$E$110,2,FALSE) -> 1 - Humidity Ratio | L19: =VLOOKUP($B19,Legend!$B$2:$E$110,4,FALSE) -> °F
A20: 0 | B20: Sensible | C20: 210 | D20: 0 | E20: 0 | F20: 0 | G20: 0 | H20: 0 | I20: 0 | J20: 0 | K20: =VLOOKUP(B20,Legend!$B$2:$E$110,2,FALSE) -> Total Sensible Heat Load | L20: =VLOOKUP($B20,Legend!$B$2:$E$110,4,FALSE) -> BTU/sec
A21: 0 | B21: Latent | C21: 179 | D21: 0.00040133565 | E21: 0.005369505 | F21: 0 | G21: 0 | H21: 0 | I21: 0 | J21: 0.07183908 | K21: =VLOOKUP(B21,Legend!$B$2:$E$110,2,FALSE) -> Total Latent Heat Load | L21: =VLOOKUP($B21,Legend!$B$2:$E$110,4,FALSE) -> BTU/sec
A22: TRA | B22: RTE | C22: 41 | D22: 0 | E22: 0 | F22: 0 | G22: 0 | H22: 0 | I22: 0 | J22: 0 | K22: =VLOOKUP(B22,Legend!$B$2:$E$110,2,FALSE) -> Train route | L22: =VLOOKUP($B22,Legend!$B$2:$E$110,4,FALSE) -> #
A23: 0 | B23: TYP | C23: 41 | D23: 0 | E23: 0 | F23: 0 | G23: 0 | H23: 0 | I23: 0 | J23: 0 | K23: =VLOOKUP(B23,Legend!$B$2:$E$110,2,FALSE) -> Train Type | L23: =VLOOKUP($B23,Legend!$B$2:$E$110,4,FALSE) -> #
A24: 0 | B24: Location | C24: 41 | D24: 0 | E24: 0 | F24: 0 | G24: 0 | H24: 0 | I24: 0 | J24: 0 | K24: =VLOOKUP(B24,Legend!$B$2:$E$110,2,FALSE) -> Train Location | L24: =VLOOKUP($B24,Legend!$B$2:$E$110,4,FALSE) -> ft
A25: 0 | B25: Speed | C25: 35 | D25: 0 | E25: 0 | F25: 0 | G25: 0 | H25: 0 | I25: 0 | J25: 0 | K25: =VLOOKUP(B25,Legend!$B$2:$E$110,2,FALSE) -> Train Speed | L25: =VLOOKUP($B25,Legend!$B$2:$E$110,4,FALSE) -> mph
A26: 0 | B26: Accel | C26: 32 | D26: 0 | E26: 0 | F26: 0 | G26: 0 | H26: 0 | I26: 0 | J26: 0 | K26: =VLOOKUP(B26,Legend!$B$2:$E$110,2,FALSE) -> Train Acceleration | L26: =VLOOKUP($B26,Legend!$B$2:$E$110,4,FALSE) -> mph/sec
A27: 0 | B27: Drag_KN | C27: 33 | D27: 0 | E27: 0 | F27: 0 | G27: 0 | H27: 0 | I27: 0 | J27: 0 | K27: =VLOOKUP(B27,Legend!$B$2:$E$110,2,FALSE) -> Air Drag (KN) | L27: =VLOOKUP($B27,Legend!$B$2:$E$110,4,FALSE) -> lbs
A28: 0 | B28: Drag_COEFF | C28: 33 | D28: 0 | E28: 0 | F28: 0 | G28: 0 | H28: 0 | I28: 0 | J28: 0 | K28: =VLOOKUP(B28,Legend!$B$2:$E$110,2,FALSE) -> Air Drag (COEFF) | L28: =VLOOKUP($B28,Legend!$B$2:$E$110,4,FALSE) -> #
A29: 0 | B29: Tractive | C29: 20 | D29: 0 | E29: 0 | F29: 0 | G29: 0 | H29: 0 | I29: 0 | J29: 0 | K29: =VLOOKUP(B29,Legend!$B$2:$E$110,2,FALSE) -> Tractive Effort | L29: =VLOOKUP($B29,Legend!$B$2:$E$110,4,FALSE) -> lbs/motor
A30: 0 | B30: M_Current | C30: 20 | D30: 0 | E30: 0 | F30: 0 | G30: 0 | H30: 0 | I30: 0 | J30: 0 | K30: =VLOOKUP(B30,Legend!$B$2:$E$110,2,FALSE) -> Motor Current | L30: =VLOOKUP($B30,Legend!$B$2:$E$110,4,FALSE) -> amps
A31: 0 | B31: L_Current | C31: 18 | D31: 0 | E31: 0 | F31: 0 | G31: 0 | H31: 0 | I31: 0 | J31: 0 | K31: =VLOOKUP(B31,Legend!$B$2:$E$110,2,FALSE) -> Line Current | L31: =VLOOKUP($B31,Legend!$B$2:$E$110,4,FALSE) -> amps
A32: 0 | B32: FLY | C32: 20 | D32: 0 | E32: 0 | F32: 0 | G32: 0 | H32: 0 | I32: 0 | J32: 0 | K32: =VLOOKUP(B32,Legend!$B$2:$E$110,2,FALSE) -> Fly Wheel | L32: =VLOOKUP($B32,Legend!$B$2:$E$110,4,FALSE) -> RPM
A33: 0 | B33: M_Eff | C33: 0 | D33: 0 | E33: 0 | F33: 0 | G33: 0 | H33: 0 | I33: 0 | J33: 0 | K33: =VLOOKUP(B33,Legend!$B$2:$E$110,2,FALSE) -> Motor Efficiency | L33: =VLOOKUP($B33,Legend!$B$2:$E$110,4,FALSE) -> 0
A34: 0 | B34: G_Accel | C34: 41 | D34: 0 | E34: 0 | F34: 0 | G34: 0 | H34: 0 | I34: 0 | J34: 0 | K34: =VLOOKUP(B34,Legend!$B$2:$E$110,2,FALSE) -> Grid Temperature Acceleration | L34: =VLOOKUP($B34,Legend!$B$2:$E$110,4,FALSE) -> °F
... A37: 0 | B37: H_Reject | C37: 41 | D37: 0.0015485869 | E37: 0.0099157944 | F37: 0 | G37: 0 | H37: 0 | I37: 0 | J37: 0.063492063 | K37: =VLOOKUP(B37,Legend!$B$2:$E$110,2,FALSE) -> Heat rejected | L37: =VLOOKUP($B37,Legend!$B$2:$E$110,4,FALSE) -> BTU/SEC-FT
A38: SEG | B38: A_Max | C38: 72 | D38: 5.5555556e-05 | E38: 0.00028526681 | F38: -0.001 | G38: 0 | H38: 0 | I38: 0 | J38: 0.001 | K38: =VLOOKUP(B38,Legend!$B$2:$E$110,2,FALSE) -> Airflow rate maximum | L38: =VLOOKUP($B38,Legend!$B$2:$E$110,4,FALSE) -> kCFM
A39: 0 | B39: A_Max_T | C39: 72 | D39: 0 | E39: 0 | F39: 0 | G39: 0 | H39: 0 | I39: 0 | J39: 0 | K39: =VLOOKUP(B39,Legend!$B$2:$E$110,2,FALSE) -> Time of airflow rate maximum | L39: =VLOOKUP($B39,Legend!$B$2:$E$110,4,FALSE) -> seconds
A40: 0 | B40: A_Min | C40: 72 | D40: 0.00022222222 | E40: 0.00053660965 | F40: -0.001 | G40: 0 | H40: 0 | I40: 0.00025 | J40: 0.002 | K40: =VLOOKUP(B40,Legend!$B$2:$E$110,2,FALSE) -> Airflow rate minimum | L40: =VLOOKUP($B40,Legend!$B$2:$E$110,4,FALSE) -> kCFM
A41: 0 | B41: A_Min_T | C41: 72 | D41: 0 | E41: 0 | F41: 0 | G41: 0 | H41: 0 | I41: 0 | J41: 0 | K41: =VLOOKUP(B41,Legend!$B$2:$E$110,2,FALSE) -> Time of airflow rate minimum | L41: =VLOOKUP($B41,Legend!$B$2:$E$110,4,FALSE) -> seconds
A42: 0 | B42: A_P | C42: 72 | D42: 8.3333333e-05 | E42: 0.00032501354 | F42: -0.001 | G42: 0 | H42: 0 | I42: 0 | J42: 0.001 | K42: =VLOOKUP(B42,Legend!$B$2:$E$110,2,FALSE) -> Airflow rate average value - positive | L42: =VLOOKUP($B42,Legend!$B$2:$E$110,4,FALSE) -> kCFM
A43: 0 | B43: A_N | C43: 72 | D43: 5.5555556e-05 | E43: 0.00023066889 | F43: 0 | G43: 0 | H43: 0 | I43: 0 | J43: 0.001 | K43: =VLOOKUP(B43,Legend!$B$2:$E$110,2,FALSE) -> Airflow rate average value - negative | L43: =VLOOKUP($B43,Legend!$B$2:$E$110,4,FALSE) -> kCFM
A44: 0 | B44: V_Max | C44: 72 | D44: 0 | E44: 0 | F44: 0 | G44: 0 | H44: 0 | I44: 0 | J44: 0 | K44: =VLOOKUP(B44,Legend!$B$2:$E$110,2,FALSE) -> Air velocity maximum | L44: =VLOOKUP($B44,Legend!$B$2:$E$110,4,FALSE) -> FPM
...

Sheet Legend
A1: Sheet Name | B1: Heading | C1: Full description | D1: SI Unit | E1: IP Unit | F1: Note
A2: SSA | B2: Second-by-second aerodynamic data
B3: Time | C3: Simulation Time | D3: Sec | E3: Sec
B4: Segment | C4: Segment numbers | D4: # | E4: #
B5: ID | C5: Title | F5: Time-Segement (TTT-SSS)
B6: Title
B7: Airflow | C7: Section Air Flow Rate | D7: m3/s | E7: kCFM | F7: CFM is divided by 1,000 to convert to kcfm
B8: AirVel | C8: Bulk Air Velocity | D8: m/s | E8: FPM
A9: SST | B9: Second-by-second thermodynamic data
B10: Time | C10: Simulation Time | D10: Sec | E10: Sec
B11: Segment | C11: Segment numbers | D11: # | E11: #
B12: Sub | C12: Sub-segment number | D12: # | E12: #
B13: ID
B14: Sensible | C14: Total Sensible Heat Load | D14: W | E14: BTU/sec
B15: Latent | C15: Total Latent Heat Load | D15: W | E15: BTU/sec
B16: AirTemp | C16: Air Dry-Bulb Temperature | D16: °C | E16: °F
B17: Humidity | C17: 1 - Humidity Ratio | D17: kg/kg | E17: °F
B18: WallTemp | C18: Wall Surface Temperature | D18: °C | E18: °F
B19: WallConvection | C19: Heat Transfer to Wall by Convection | D19: W | E19: BTU/Hr
B20: WallRadiation | C20: Heat Transfer to Wall by Radiation | D20: W | E20: BTU/Hr
B21: FluidTemp | C21: Working Fluid Temperature | D21: °C
B22: FuildHeat | C22: Heat Absorbed by Cooling Pipe | D22: W
A23: TRA | B23: Secod-by-second Train data
B24: Time | C24: Time | D24: Sec | E24: Sec
B25: Number | C25: Train ID Number | D25: # | E25: #
B26: RTE | C26: Train route | D26: # | E26: #
B27: TYP | C27: Train Type | D27: # | E27: #
B28: Location | C28: Train Location | D28: m | E28: ft
B29: Speed | C29: Train Speed | D29: kph | E29: mph
B30: Accel | C30: Train Acceleration | D30: m/s2 | E30: mph/sec
B31: Drag_KN | C31: Air Drag (KN) | D31: kN | E31: lbs
B32: Drag_COEFF | C32: Air Drag (COEFF) | D32: # | E32: #
B33: Tractive | C33: Tractive Effort | D33: N/motor | E33: lbs/motor
B34: M_Current | C34: Motor Current | D34: amps | E34: amps
B35: L_Current | C35: Line Current | D35: amps | E35: amps
B36: FLY | C36: Fly Wheel | D36: RPM | E36: RPM
B37: M_Eff | C37: Motor Efficiency | D37: %
B38: G_Accel | C38: Grid Temperature Acceleration | D38: °C | E38: °F
B39: G_Decel | C39: Grid Temperature Deceleration | D39: °C | E39: °F
B40: H_Gen | C40: Heat generated | D40: W/m | E40: BTU/SEC-FT
...

Sheet SSA
A1: Next-Vis Sheet: SSA
A2: Summary
A3: Percent Error = Absolute value of [(Difference) / (4p2\normal.PRN)] x 100% | F3: Difference = (4p2\normal4p2.out) - (4p2\normal.PRN)
C4: Airflow | D4: AirVel | H4: Airflow | I4: AirVel
B5: count | C5: 288 | D5: 288 | G5: count | H5: 306 | I5: 306
B6: mean | C6: 0.00036919344 | D6: 0.00011838846 | G6: mean | H6: 6.0784314e-05 | I6: 3.7152561e-16
B7: std | C7: 0.0011293255 | D7: 0.0014579093 | G7: std | H7: 0.00033559056 | I7: 0.0080977633
B8: min | C8: 0 | D8: 0 | G8: min | H8: -0.0008 | I8: -0.1
B9: 25% | C9: 0 | D9: 0 | G9: 25% | H9: -0.0001 | I9: 0
B10: 50% | C10: 6.1007583e-05 | D10: 0 | G10: 50% | H10: 0 | I10: 0
B11: 75% | C11: 0.00026707333 | D11: 0 | G11: 75% | H11: 0.0001 | I11: 0
B12: max | C12: 0.012537613 | D12: 0.021097046 | G12: max | H12: 0.0016 | I12: 0.1
A13: Data
A14: Percent Error = Absolute value of [(Difference) / (4p2\normal.PRN)] x 100% | F14: Difference = (4p2\normal4p2.out) - (4p2\normal.PRN) | K14: 4p2\normal4p2.out | P14: 4p2\normal.PRN
A15: Time | B15: Segment | C15: Airflow | D15: AirVel | F15: Time | G15: Segment | H15: Airflow | I15: AirVel | K15: Time | L15: Segment | M15: Airflow | N15: AirVel | P15: Time | Q15: Segment | R15: Airflow | S15: AirVel
A16: 0 | B16: 1 | F16: 0 | G16: 1 | H16: 0 | I16: 0 | K16: 0 | L16: 1 | M16: 0 | N16: 0 | P16: 0 | Q16: 1 | R16: 0 | S16: 0
A17: 0 | B17: 2 | F17: 0 | G17: 2 | H17: 0 | I17: 0 | K17: 0 | L17: 2 | M17: 0 | N17: 0 | P17: 0 | Q17: 2 | R17: 0 | S17: 0
A18: 0 | B18: 3 | F18: 0 | G18: 3 | H18: 0 | I18: 0 | K18: 0 | L18: 3 | M18: 0 | N18: 0 | P18: 0 | Q18: 3 | R18: 0 | S18: 0
A19: 0 | B19: 4 | F19: 0 | G19: 4 | H19: 0 | I19: 0 | K19: 0 | L19: 4 | M19: 0 | N19: 0 | P19: 0 | Q19: 4 | R19: 0 | S19: 0
A20: 0 | B20: 5 | F20: 0 | G20: 5 | H20: 0 | I20: 0 | K20: 0 | L20: 5 | M20: 0 | N20: 0 | P20: 0 | Q20: 5 | R20: 0 | S20: 0
A21: 0 | B21: 6 | F21: 0 | G21: 6 | H21: 0 | I21: 0 | K21: 0 | L21: 6 | M21: 0 | N21: 0 | P21: 0 | Q21: 6 | R21: 0 | S21: 0
A22: 0 | B22: 7 | F22: 0 | G22: 7 | H22: 0 | I22: 0 | K22: 0 | L22: 7 | M22: 0 | N22: 0 | P22: 0 | Q22: 7 | R22: 0 | S22: 0
A23: 0 | B23: 8 | F23: 0 | G23: 8 | H23: 0 | I23: 0 | K23: 0 | L23: 8 | M23: 0 | N23: 0 | P23: 0 | Q23: 8 | R23: 0 | S23: 0
A24: 0 | B24: 9 | F24: 0 | G24: 9 | H24: 0 | I24: 0 | K24: 0 | L24: 9 | M24: 0 | N24: 0 | P24: 0 | Q24: 9 | R24: 0 | S24: 0
A25: 0 | B25: 10 | F25: 0 | G25: 10 | H25: 0 | I25: 0 | K25: 0 | L25: 10 | M25: 0 | N25: 0 | P25: 0 | Q25: 10 | R25: 0 | S25: 0
A26: 0 | B26: 11 | F26: 0 | G26: 11 | H26: 0 | I26: 0 | K26: 0 | L26: 11 | M26: 0 | N26: 0 | P26: 0 | Q26: 11 | R26: 0 | S26: 0
A27: 0 | B27: 12 | F27: 0 | G27: 12 | H27: 0 | I27: 0 | K27: 0 | L27: 12 | M27: 0 | N27: 0 | P27: 0 | Q27: 12 | R27: 0 | S27: 0
... A33: 0 | B33: 114 | F33: 0 | G33: 114 | H33: 0 | I33: 0 | K33: 0 | L33: 114 | M33: 0 | N33: 0 | P33: 0 | Q33: 114 | R33: 0 | S33: 0
A34: 180 | B34: 1 | C34: 0.0015102318 | D34: 0 | F34: 180 | G34: 1 | H34: -0.0006 | I34: 0 | K34: 180 | L34: 1 | M34: 39.7284 | N34: 132.4 | P34: 180 | Q34: 1 | R34: 39.729 | S34: 132.4
A35: 180 | B35: 2 | C35: 0.0015102318 | D35: 0 | F35: 180 | G35: 2 | H35: -0.0006 | I35: 0 | K35: 180 | L35: 2 | M35: 39.7284 | N35: 158.9 | P35: 180 | Q35: 2 | R35: 39.729 | S35: 158.9
A36: 180 | B36: 3 | C36: 0.0015102318 | D36: 0 | F36: 180 | G36: 3 | H36: -0.0006 | I36: 0 | K36: 180 | L36: 3 | M36: 39.7284 | N36: 176.6 | P36: 180 | Q36: 3 | R36: 39.729 | S36: 176.6
A37: 180 | B37: 4 | C37: 0.00015697473 | D37: 0 | F37: 180 | G37: 4 | H37: 0.0005 | I37: 0 | K37: 180 | L37: 4 | M37: -318.5221 | N37: -1415.7 | P37: 180 | Q37: 4 | R37: -318.5226 | S37: -1415.7
A38: 180 | B38: 5 | C38: 0.0011706899 | D38: 0 | F38: 180 | G38: 5 | H38: -0.0007 | I38: 0 | K38: 180 | L38: 5 | M38: -59.7945 | N38: -265.8 | P38: 180 | Q38: 5 | R38: -59.7938 | S38: -265.8
A39: 180 | B39: 6 | C39: 0.00013203342 | D39: 0 | F39: 180 | G39: 6 | H39: 0.0004 | I39: 0 | K39: 180 | L39: 6 | M39: -302.9532 | N39: -1346.5 | P39: 180 | Q39: 6 | R39: -302.9536 | S39: -1346.5
A40: 180 | B40: 7 | C40: 8.2702178e-05 | D40: 0 | F40: 180 | G40: 7 | H40: -0.0003 | I40: 0 | K40: 180 | L40: 7 | M40: -362.7477 | N40: -518.2 | P40: 180 | Q40: 7 | R40: -362.7474 | S40: -518.2
A41: 180 | B41: 8 | C41: 0.00064283878 | D41: 0 | F41: 180 | G41: 8 | H41: -0.0001 | I41: 0 | K41: 180 | L41: 8 | M41: 15.5559 | N41: 34.6 | P41: 180 | Q41: 8 | R41: 15.556 | S41: 34.6
A42: 180 | B42: 9 | C42: 5.2867619e-05 | D42: 0 | F42: 180 | G42: 9 | H42: -0.0002 | I42: 0 | K42: 180 | L42: 9 | M42: -378.3036 | N42: -540.4 | P42: 180 | Q42: 9 | R42: -378.3034 | S42: -540.4
A43: 180 | B43: 10 | C43: 0 | D43: 0 | F43: 180 | G43: 10 | H43: 0 | I43: 0 | K43: 180 | L43: 10 | M43: 51.2503 | N43: 113.9 | P43: 180 | Q43: 10 | R43: 51.2503 | S43: 113.9
A44: 180 | B44: 11 | C44: 6.1152149e-05 | D44: 0 | F44: 180 | G44: 11 | H44: -0.0002 | I44: 0 | K44: 180 | L44: 11 | M44: -327.0533 | N44: -467.2 | P44: 180 | Q44: 11 | R44: -327.0531 | S44: -467.2
A45: 180 | B45: 12 | C45: 6.1152149e-05 | D45: 0 | F45: 180 | G45: 12 | H45: -0.0002 | I45: 0 | K45: 180 | L45: 12 | M45: -327.0533 | N45: -817.6 | P45: 180 | Q45: 12 | R45: -327.0531 | S45: -817.6
...

Sheet SST
A1: Next-Vis Sheet: SST
A2: Summary
B3: Percent Error = Absolute value of [(Difference) / (4p2\normal.PRN)] x 100% | I3: Difference = (4p2\normal4p2.out) - (4p2\normal.PRN)
D4: AirTemp | E4: Humidity | F4: Sensible | G4: Latent | L4: AirTemp | M4: Humidity | N4: Sensible | O4: Latent
C5: count | D5: 418 | E5: 418 | F5: 210 | G5: 179 | K5: count | L5: 418 | M5: 418 | N5: 210 | O5: 210
C6: mean | D6: 0.01279533 | E6: 0.058289486 | F6: 0 | G6: 0.00040133565 | K6: mean | L6: -0.0012679426 | M6: 1.4114833e-06 | N6: 0 | O6: 0.00047619048
C7: std | D7: 0.018097983 | E7: 0.092496412 | F7: 0 | G7: 0.005369505 | K7: std | L7: 0.019219045 | M7: 1.8050504e-05 | N7: 0 | O7: 0.0069006556
C8: min | D8: 0 | E8: 0 | F8: 0 | G8: 0 | K8: min | L8: -0.05 | M8: -5e-05 | N8: 0 | O8: 0
C9: 25% | D9: 0 | E9: 0 | F9: 0 | G9: 0 | K9: 25% | L9: 0 | M9: 0 | N9: 0 | O9: 0
C10: 50% | D10: 0 | E10: 0 | F10: 0 | G10: 0 | K10: 50% | L10: 0 | M10: 0 | N10: 0 | O10: 0
C11: 75% | D11: 0.023337223 | E11: 0.099009901 | F11: 0 | G11: 0 | K11: 75% | L11: 0 | M11: 0 | N11: 0 | O11: 0
C12: max | D12: 0.06090134 | E12: 0.47169811 | F12: 0 | G12: 0.07183908 | K12: max | L12: 0.05 | M12: 5e-05 | N12: 0 | O12: 0.1
A13: Data
A14: Percent Error = Absolute value of [(Difference) / (4p2\normal.PRN)] x 100% | I14: Difference = (4p2\normal4p2.out) - (4p2\normal.PRN) | Q14: 4p2\normal4p2.out | Y14: 4p2\normal.PRN
A15: Time | B15: Segment | C15: Sub | D15: AirTemp | E15: Humidity | F15: Sensible | G15: Latent | I15: Time | J15: Segment | K15: Sub | L15: AirTemp | M15: Humidity | N15: Sensible | O15: Latent | Q15: Time | R15: Segment | S15: Sub | T15: AirTemp | U15: Humidity | V15: Sensible | W15: Latent | Y15: Time | Z15: Segment | AA15: Sub | AB15: AirTemp | AC15: Humidity | AD15: Sensible | AE15: Latent
A16: 0 | B16: 1 | C16: 1 | D16: 0 | E16: 0 | F16: 0 | I16: 0 | J16: 1 | K16: 1 | L16: 0 | M16: 0 | N16: 0 | O16: 0 | Q16: 0 | R16: 1 | S16: 1 | T16: 90 | U16: 0.02017 | V16: 0.2 | W16: 0 | Y16: 0 | Z16: 1 | AA16: 1 | AB16: 90 | AC16: 0.02017 | AD16: 0.2 | AE16: 0
A17: 0 | B17: 2 | C17: 1 | D17: 0 | E17: 0 | F17: 0 | I17: 0 | J17: 2 | K17: 1 | L17: 0 | M17: 0 | N17: 0 | O17: 0 | Q17: 0 | R17: 2 | S17: 1 | T17: 90 | U17: 0.02017 | V17: 0.2 | W17: 0 | Y17: 0 | Z17: 2 | AA17: 1 | AB17: 90 | AC17: 0.02017 | AD17: 0.2 | AE17: 0
A18: 0 | B18: 3 | C18: 1 | D18: 0 | E18: 0 | F18: 0 | I18: 0 | J18: 3 | K18: 1 | L18: 0 | M18: 0 | N18: 0 | O18: 0 | Q18: 0 | R18: 3 | S18: 1 | T18: 90 | U18: 0.02017 | V18: 0.4 | W18: 0 | Y18: 0 | Z18: 3 | AA18: 1 | AB18: 90 | AC18: 0.02017 | AD18: 0.4 | AE18: 0
A19: 0 | B19: 3 | C19: 2 | D19: 0 | E19: 0 | F19: 0 | I19: 0 | J19: 3 | K19: 2 | L19: 0 | M19: 0 | N19: 0 | O19: 0 | Q19: 0 | R19: 3 | S19: 2 | T19: 90 | U19: 0.02017 | V19: 0.4 | W19: 0 | Y19: 0 | Z19: 3 | AA19: 2 | AB19: 90 | AC19: 0.02017 | AD19: 0.4 | AE19: 0
A20: 0 | B20: 4 | C20: 1 | D20: 0 | E20: 0 | F20: 0 | I20: 0 | J20: 4 | K20: 1 | L20: 0 | M20: 0 | N20: 0 | O20: 0 | Q20: 0 | R20: 4 | S20: 1 | T20: 90 | U20: 0.02017 | V20: 2.5 | W20: 0 | Y20: 0 | Z20: 4 | AA20: 1 | AB20: 90 | AC20: 0.02017 | AD20: 2.5 | AE20: 0
A21: 0 | B21: 4 | C21: 2 | D21: 0 | E21: 0 | F21: 0 | I21: 0 | J21: 4 | K21: 2 | L21: 0 | M21: 0 | N21: 0 | O21: 0 | Q21: 0 | R21: 4 | S21: 2 | T21: 90 | U21: 0.02017 | V21: 2.5 | W21: 0 | Y21: 0 | Z21: 4 | AA21: 2 | AB21: 90 | AC21: 0.02017 | AD21: 2.5 | AE21: 0
A22: 0 | B22: 4 | C22: 3 | D22: 0 | E22: 0 | F22: 0 | I22: 0 | J22: 4 | K22: 3 | L22: 0 | M22: 0 | N22: 0 | O22: 0 | Q22: 0 | R22: 4 | S22: 3 | T22: 90 | U22: 0.02017 | V22: 2.5 | W22: 0 | Y22: 0 | Z22: 4 | AA22: 3 | AB22: 90 | AC22: 0.02017 | AD22: 2.5 | AE22: 0
A23: 0 | B23: 5 | C23: 1 | D23: 0 | E23: 0 | F23: 0 | I23: 0 | J23: 5 | K23: 1 | L23: 0 | M23: 0 | N23: 0 | O23: 0 | Q23: 0 | R23: 5 | S23: 1 | T23: 90 | U23: 0.02017 | V23: 0.4 | W23: 0 | Y23: 0 | Z23: 5 | AA23: 1 | AB23: 90 | AC23: 0.02017 | AD23: 0.4 | AE23: 0
A24: 0 | B24: 5 | C24: 2 | D24: 0 | E24: 0 | F24: 0 | I24: 0 | J24: 5 | K24: 2 | L24: 0 | M24: 0 | N24: 0 | O24: 0 | Q24: 0 | R24: 5 | S24: 2 | T24: 90 | U24: 0.02017 | V24: 0.4 | W24: 0 | Y24: 0 | Z24: 5 | AA24: 2 | AB24: 90 | AC24: 0.02017 | AD24: 0.4 | AE24: 0
A25: 0 | B25: 5 | C25: 3 | D25: 0 | E25: 0 | F25: 0 | I25: 0 | J25: 5 | K25: 3 | L25: 0 | M25: 0 | N25: 0 | O25: 0 | Q25: 0 | R25: 5 | S25: 3 | T25: 90 | U25: 0.02017 | V25: 0.4 | W25: 0 | Y25: 0 | Z25: 5 | AA25: 3 | AB25: 90 | AC25: 0.02017 | AD25: 0.4 | AE25: 0
A26: 0 | B26: 6 | C26: 1 | D26: 0 | E26: 0 | F26: 0 | I26: 0 | J26: 6 | K26: 1 | L26: 0 | M26: 0 | N26: 0 | O26: 0 | Q26: 0 | R26: 6 | S26: 1 | T26: 90 | U26: 0.02017 | V26: 2.5 | W26: 0 | Y26: 0 | Z26: 6 | AA26: 1 | AB26: 90 | AC26: 0.02017 | AD26: 2.5 | AE26: 0
A27: 0 | B27: 6 | C27: 2 | D27: 0 | E27: 0 | F27: 0 | I27: 0 | J27: 6 | K27: 2 | L27: 0 | M27: 0 | N27: 0 | O27: 0 | Q27: 0 | R27: 6 | S27: 2 | T27: 90 | U27: 0.02017 | V27: 2.5 | W27: 0 | Y27: 0 | Z27: 6 | AA27: 2 | AB27: 90 | AC27: 0.02017 | AD27: 2.5 | AE27: 0
A28: 0 | B28: 6 | C28: 3 | D28: 0 | E28: 0 | F28: 0 | I28: 0 | J28: 6 | K28: 3 | L28: 0 | M28: 0 | N28: 0 | O28: 0 | Q28: 0 | R28: 6 | S28: 3 | T28: 90 | U28: 0.02017 | V28: 2.5 | W28: 0 | Y28: 0 | Z28: 6 | AA28: 3 | AB28: 90 | AC28: 0.02017 | AD28: 2.5 | AE28: 0
A29: 0 | B29: 7 | C29: 1 | D29: 0 | E29: 0 | F29: 0 | G29: 0 | I29: 0 | J29: 7 | K29: 1 | L29: 0 | M29: 0 | N29: 0 | O29: 0 | Q29: 0 | R29: 7 | S29: 1 | T29: 80 | U29: 0.01364 | V29: 32.6 | W29: 11.7 | Y29: 0 | Z29: 7 | AA29: 1 | AB29: 80 | AC29: 0.01364 | AD29: 32.6 | AE29: 11.7
A30: 0 | B30: 8 | C30: 1 | D30: 0 | E30: 0 | F30: 0 | I30: 0 | J30: 8 | K30: 1 | L30: 0 | M30: 0 | N30: 0 | O30: 0 | Q30: 0 | R30: 8 | S30: 1 | T30: 85 | U30: 0.01492 | V30: 22.9 | W30: 0 | Y30: 0 | Z30: 8 | AA30: 1 | AB30: 85 | AC30: 0.01492 | AD30: 22.9 | AE30: 0
A31: 0 | B31: 8 | C31: 2 | D31: 0 | E31: 0 | F31: 0 | I31: 0 | J31: 8 | K31: 2 | L31: 0 | M31: 0 | N31: 0 | O31: 0 | Q31: 0 | R31: 8 | S31: 2 | T31: 85 | U31: 0.01492 | V31: 22.9 | W31: 0 | Y31: 0 | Z31: 8 | AA31: 2 | AB31: 85 | AC31: 0.01492 | AD31: 22.9 | AE31: 0
A32: 0 | B32: 9 | C32: 1 | D32: 0 | E32: 0 | F32: 0 | G32: 0 | I32: 0 | J32: 9 | K32: 1 | L32: 0 | M32: 0 | N32: 0 | O32: 0 | Q32: 0 | R32: 9 | S32: 1 | T32: 80 | U32: 0.01364 | V32: 86.1 | W32: 17.9 | Y32: 0 | Z32: 9 | AA32: 1 | AB32: 80 | AC32: 0.01364 | AD32: 86.1 | AE32: 17.9
A33: 0 | B33: 9 | C33: 2 | D33: 0 | E33: 0 | F33: 0 | G33: 0 | I33: 0 | J33: 9 | K33: 2 | L33: 0 | M33: 0 | N33: 0 | O33: 0 | Q33: 0 | R33: 9 | S33: 2 | T33: 80 | U33: 0.01364 | V33: 93.6 | W33: 18.8 | Y33: 0 | Z33: 9 | AA33: 2 | AB33: 80 | AC33: 0.01364 | AD33: 93.6 | AE33: 18.8
A34: 0 | B34: 9 | C34: 3 | D34: 0 | E34: 0 | F34: 0 | G34: 0 | I34: 0 | J34: 9 | K34: 3 | L34: 0 | M34: 0 | N34: 0 | O34: 0 | Q34: 0 | R34: 9 | S34: 3 | T34: 80 | U34: 0.01364 | V34: 93.6 | W34: 18.8 | Y34: 0 | Z34: 9 | AA34: 3 | AB34: 80 | AC34: 0.01364 | AD34: 93.6 | AE34: 18.8
A35: 0 | B35: 9 | C35: 4 | D35: 0 | E35: 0 | F35: 0 | G35: 0 | I35: 0 | J35: 9 | K35: 4 | L35: 0 | M35: 0 | N35: 0 | O35: 0 | Q35: 0 | R35: 9 | S35: 4 | T35: 80 | U35: 0.01364 | V35: 93.6 | W35: 18.8 | Y35: 0 | Z35: 9 | AA35: 4 | AB35: 80 | AC35: 0.01364 | AD35: 93.6 | AE35: 18.8
A36: 0 | B36: 10 | C36: 1 | D36: 0 | E36: 0 | F36: 0 | I36: 0 | J36: 10 | K36: 1 | L36: 0 | M36: 0 | N36: 0 | O36: 0 | Q36: 0 | R36: 10 | S36: 1 | T36: 85 | U36: 0.01492 | V36: 22.9 | W36: 0 | Y36: 0 | Z36: 10 | AA36: 1 | AB36: 85 | AC36: 0.01492 | AD36: 22.9 | AE36: 0
A37: 0 | B37: 10 | C37: 2 | D37: 0 | E37: 0 | F37: 0 | I37: 0 | J37: 10 | K37: 2 | L37: 0 | M37: 0 | N37: 0 | O37: 0 | Q37: 0 | R37: 10 | S37: 2 | T37: 85 | U37: 0.01492 | V37: 22.9 | W37: 0 | Y37: 0 | Z37: 10 | AA37: 2 | AB37: 85 | AC37: 0.01492 | AD37: 22.9 | AE37: 0
A38: 0 | B38: 11 | C38: 1 | D38: 0 | E38: 0 | F38: 0 | G38: 0 | I38: 0 | J38: 11 | K38: 1 | L38: 0 | M38: 0 | N38: 0 | O38: 0 | Q38: 0 | R38: 11 | S38: 1 | T38: 80 | U38: 0.01364 | V38: 95.9 | W38: 18.4 | Y38: 0 | Z38: 11 | AA38: 1 | AB38: 80 | AC38: 0.01364 | AD38: 95.9 | AE38: 18.4
A39: 0 | B39: 12 | C39: 1 | D39: 0 | E39: 0 | F39: 0 | G39: 0 | I39: 0 | J39: 12 | K39: 1 | L39: 0 | M39: 0 | N39: 0 | O39: 0 | Q39: 0 | R39: 12 | S39: 1 | T39: 90 | U39: 0.02017 | V39: 39.7 | W39: 6 | Y39: 0 | Z39: 12 | AA39: 1 | AB39: 90 | AC39: 0.02017 | AD39: 39.7 | AE39: 6
A40: 0 | B40: 12 | C40: 2 | D40: 0 | E40: 0 | F40: 0 | I40: 0 | J40: 12 | K40: 2 | L40: 0 | M40: 0 | N40: 0 | O40: 0 | Q40: 0 | R40: 12 | S40: 2 | T40: 90 | U40: 0.02017 | V40: 2.4 | W40: 0 | Y40: 0 | Z40: 12 | AA40: 2 | AB40: 90 | AC40: 0.02017 | AD40: 2.4 | AE40: 0
...

Sheet TRA
A1: Next-Vis Sheet: TRA
A2: Summary
A3: Percent Error = Absolute value of [(Difference) / (4p2\normal.PRN)] x 100% | T3: Difference = (4p2\normal4p2.out) - (4p2\normal.PRN)
C4: RTE | D4: TYP | E4: Location | F4: Speed | G4: Accel | H4: Drag_KN | I4: Drag_COEFF | J4: Tractive | K4: M_Current | L4: L_Current | M4: FLY | N4: M_Eff | O4: G_Accel | P4: G_Decel | Q4: H_Gen | R4: H_Reject | V4: RTE | W4: TYP | X4: Location | Y4: Speed | Z4: Accel | AA4: Draf_KN | AB4: Draf_COEFF | AC4: Tractive | AD4: M_Current | AE4: L_Current | AF4: FLY | AG4: M_Eff | AH4: G_Accel | AI4: G_Decel | AJ4: H_Gen | AK4: H_Reject
B5: count | C5: 41 | D5: 41 | E5: 41 | F5: 35 | G5: 32 | H5: 33 | I5: 33 | J5: 20 | K5: 20 | L5: 18 | M5: 20 | N5: 0 | O5: 41 | P5: 41 | Q5: 41 | R5: 41 | U5: count | V5: 41 | W5: 41 | X5: 41 | Y5: 41 | Z5: 41 | AA5: 41 | AB5: 41 | AC5: 41 | AD5: 41 | AE5: 41 | AF5: 41 | AG5: 0 | AH5: 41 | AI5: 41 | AJ5: 41 | AK5: 41
B6: mean | C6: 0 | D6: 0 | E6: 0 | F6: 0 | G6: 0 | H6: 0 | I6: 0 | J6: 0 | K6: 0 | L6: 0 | M6: 0 | O6: 0 | P6: 0 | Q6: 0 | R6: 0.0015485869 | U6: mean | V6: 0 | W6: 0 | X6: 0 | Y6: 0 | Z6: 0 | AA6: 0 | AB6: 0 | AC6: 0 | AD6: 0 | AE6: 0 | AF6: 0 | AH6: 0 | AI6: 0 | AJ6: 0 | AK6: 2.4390244e-05
B7: std | C7: 0 | D7: 0 | E7: 0 | F7: 0 | G7: 0 | H7: 0 | I7: 0 | J7: 0 | K7: 0 | L7: 0 | M7: 0 | O7: 0 | P7: 0 | Q7: 0 | R7: 0.0099157944 | U7: std | V7: 0 | W7: 0 | X7: 0 | Y7: 0 | Z7: 0 | AA7: 0 | AB7: 0 | AC7: 0 | AD7: 0 | AE7: 0 | AF7: 0 | AH7: 0 | AI7: 0 | AJ7: 0 | AK7: 0.00015617376
B8: min | C8: 0 | D8: 0 | E8: 0 | F8: 0 | G8: 0 | H8: 0 | I8: 0 | J8: 0 | K8: 0 | L8: 0 | M8: 0 | O8: 0 | P8: 0 | Q8: 0 | R8: 0 | U8: min | V8: 0 | W8: 0 | X8: 0 | Y8: 0 | Z8: 0 | AA8: 0 | AB8: 0 | AC8: 0 | AD8: 0 | AE8: 0 | AF8: 0 | AH8: 0 | AI8: 0 | AJ8: 0 | AK8: 0
B9: 25% | C9: 0 | D9: 0 | E9: 0 | F9: 0 | G9: 0 | H9: 0 | I9: 0 | J9: 0 | K9: 0 | L9: 0 | M9: 0 | O9: 0 | P9: 0 | Q9: 0 | R9: 0 | U9: 25% | V9: 0 | W9: 0 | X9: 0 | Y9: 0 | Z9: 0 | AA9: 0 | AB9: 0 | AC9: 0 | AD9: 0 | AE9: 0 | AF9: 0 | AH9: 0 | AI9: 0 | AJ9: 0 | AK9: 0
B10: 50% | C10: 0 | D10: 0 | E10: 0 | F10: 0 | G10: 0 | H10: 0 | I10: 0 | J10: 0 | K10: 0 | L10: 0 | M10: 0 | O10: 0 | P10: 0 | Q10: 0 | R10: 0 | U10: 50% | V10: 0 | W10: 0 | X10: 0 | Y10: 0 | Z10: 0 | AA10: 0 | AB10: 0 | AC10: 0 | AD10: 0 | AE10: 0 | AF10: 0 | AH10: 0 | AI10: 0 | AJ10: 0 | AK10: 0
B11: 75% | C11: 0 | D11: 0 | E11: 0 | F11: 0 | G11: 0 | H11: 0 | I11: 0 | J11: 0 | K11: 0 | L11: 0 | M11: 0 | O11: 0 | P11: 0 | Q11: 0 | R11: 0 | U11: 75% | V11: 0 | W11: 0 | X11: 0 | Y11: 0 | Z11: 0 | AA11: 0 | AB11: 0 | AC11: 0 | AD11: 0 | AE11: 0 | AF11: 0 | AH11: 0 | AI11: 0 | AJ11: 0 | AK11: 0
B12: max | C12: 0 | D12: 0 | E12: 0 | F12: 0 | G12: 0 | H12: 0 | I12: 0 | J12: 0 | K12: 0 | L12: 0 | M12: 0 | O12: 0 | P12: 0 | Q12: 0 | R12: 0.063492063 | U12: max | V12: 0 | W12: 0 | X12: 0 | Y12: 0 | Z12: 0 | AA12: 0 | AB12: 0 | AC12: 0 | AD12: 0 | AE12: 0 | AF12: 0 | AH12: 0 | AI12: 0 | AJ12: 0 | AK12: 0.001
A13: Data
A14: Percent Error = Absolute value of [(Difference) / (4p2\normal.PRN)] x 100% | T14: Difference = (4p2\normal4p2.out) - (4p2\normal.PRN) | AM14: 4p2\normal4p2.out | BF14: 4p2\normal.PRN
A15: Time | B15: Number | C15: RTE | D15: TYP | E15: Location | F15: Speed | G15: Accel | H15: Draf_KN | I15: Draf_COEFF | J15: Tractive | K15: M_Current | L15: L_Current | M15: FLY | N15: M_Eff | O15: G_Accel | P15: G_Decel | Q15: H_Gen | R15: H_Reject | T15: Time | U15: Number | V15: RTE | W15: TYP | X15: Location | Y15: Speed | Z15: Accel | AA15: Draf_KN | AB15: Draf_COEFF | AC15: Tractive | AD15: M_Current | AE15: L_Current | AF15: FLY | AG15: M_Eff | AH15: G_Accel | AI15: G_Decel | AJ15: H_Gen | AK15: H_Reject | AM15: Time | AN15: Number | AO15: RTE | AP15: TYP | AQ15: Location | AR15: Speed | AS15: Accel | AT15: Draf_KN | AU15: Draf_COEFF | AV15: Tractive | AW15: M_Current | AX15: L_Current | AY15: FLY | AZ15: M_Eff | BA15: G_Accel | BB15: G_Decel | BC15: H_Gen | BD15: H_Reject | BF15: Time | BG15: Number | BH15: RTE | BI15: TYP | BJ15: Location | BK15: Speed | BL15: Accel | BM15: Draf_KN | BN15: Draf_COEFF | BO15: Tractive | BP15: M_Current | BQ15: L_Current | BR15: FLY | BS15: M_Eff | BT15: G_Accel | BU15: G_Decel | BV15: H_Gen | BW15: H_Reject
A16: 0 | B16: 1 | C16: 0 | D16: 0 | E16: 0 | F16: 0 | G16: 0 | J16: 0 | K16: 0 | L16: 0 | O16: 0 | P16: 0 | Q16: 0 | R16: 0 | T16: 0 | U16: 1 | V16: 0 | W16: 0 | X16: 0 | Y16: 0 | Z16: 0 | AA16: 0 | AB16: 0 | AC16: 0 | AD16: 0 | AE16: 0 | AF16: 0 | AH16: 0 | AI16: 0 | AJ16: 0 | AK16: 0 | AM16: 0 | AN16: 1 | AO16: 1 | AP16: 1 | AQ16: 2877.21 | AR16: 19.25 | AS16: 3 | AT16: 0 | AU16: 0 | AV16: 5412 | AW16: 900 | AX16: 959 | AY16: 0 | BA16: 276 | BB16: 740.1 | BC16: 0.434 | BD16: 0.434 | BF16: 0 | BG16: 1 | BH16: 1 | BI16: 1 | BJ16: 2877.21 | BK16: 19.25 | BL16: 3 | BM16: 0 | BN16: 0 | BO16: 5412 | BP16: 900 | BQ16: 959 | BR16: 0 | BT16: 276 | BU16: 740.1 | BV16: 0.434 | BW16: 0.434
A17: 0 | B17: 2 | C17: 0 | D17: 0 | E17: 0 | F17: 0 | G17: 0 | J17: 0 | K17: 0 | L17: 0 | M17: 0 | O17: 0 | P17: 0 | Q17: 0 | R17: 0 | T17: 0 | U17: 2 | V17: 0 | W17: 0 | X17: 0 | Y17: 0 | Z17: 0 | AA17: 0 | AB17: 0 | AC17: 0 | AD17: 0 | AE17: 0 | AF17: 0 | AH17: 0 | AI17: 0 | AJ17: 0 | AK17: 0 | AM17: 0 | AN17: 2 | AO17: 2 | AP17: 2 | AQ17: 2744.71 | AR17: 11 | AS17: 3 | AT17: 0 | AU17: 0 | AV17: 6693 | AW17: 900 | AX17: 756 | AY17: 10000 | BA17: 241.6 | BB17: 751.3 | BC17: 0.369 | BD17: 0.369 | BF17: 0 | BG17: 2 | BH17: 2 | BI17: 2 | BJ17: 2744.71 | BK17: 11 | BL17: 3 | BM17: 0 | BN17: 0 | BO17: 6693 | BP17: 900 | BQ17: 756 | BR17: 10000 | BT17: 241.6 | BU17: 751.3 | BV17: 0.369 | BW17: 0.369
A18: 180 | B18: 5 | C18: 0 | D18: 0 | E18: 0 | F18: 0 | G18: 0 | H18: 0 | I18: 0 | J18: 0 | K18: 0 | L18: 0 | O18: 0 | P18: 0 | Q18: 0 | R18: 0 | T18: 180 | U18: 5 | V18: 0 | W18: 0 | X18: 0 | Y18: 0 | Z18: 0 | AA18: 0 | AB18: 0 | AC18: 0 | AD18: 0 | AE18: 0 | AF18: 0 | AH18: 0 | AI18: 0 | AJ18: 0 | AK18: 0 | AM18: 180 | AN18: 5 | AO18: 1 | AP18: 1 | AQ18: 2787.13 | AR18: 5.4 | AS18: 3 | AT18: 110 | AU18: 15.79 | AV18: 5166 | AW18: 791 | AX18: 299 | AY18: 0 | BA18: 90 | BB18: 611.9 | BC18: 0.885 | BD18: 1.413 | BF18: 180 | BG18: 5 | BH18: 1 | BI18: 1 | BJ18: 2787.13 | BK18: 5.4 | BL18: 3 | BM18: 110 | BN18: 15.79 | BO18: 5166 | BP18: 791 | BQ18: 299 | BR18: 0 | BT18: 90 | BU18: 611.9 | BV18: 0.885 | BW18: 1.413
A19: 180 | B19: 6 | C19: 0 | D19: 0 | E19: 0 | F19: 0 | G19: 0 | H19: 0 | I19: 0 | M19: 0 | O19: 0 | P19: 0 | Q19: 0 | R19: 0 | T19: 180 | U19: 6 | V19: 0 | W19: 0 | X19: 0 | Y19: 0 | Z19: 0 | AA19: 0 | AB19: 0 | AC19: 0 | AD19: 0 | AE19: 0 | AF19: 0 | AH19: 0 | AI19: 0 | AJ19: 0 | AK19: 0 | AM19: 180 | AN19: 6 | AO19: 2 | AP19: 2 | AQ19: 2636.93 | AR19: 23.2 | AS19: -2.76 | AT19: 45 | AU19: 0.35 | AV19: 0 | AW19: 0 | AX19: 0 | AY19: 12997 | BA19: 90 | BB19: 571.9 | BC19: 1.555 | BD19: 2.182 | BF19: 180 | BG19: 6 | BH19: 2 | BI19: 2 | BJ19: 2636.93 | BK19: 23.2 | BL19: -2.76 | BM19: 45 | BN19: 0.35 | BO19: 0 | BP19: 0 | BQ19: 0 | BR19: 12997 | BT19: 90 | BU19: 571.9 | BV19: 1.555 | BW19: 2.182
A20: 270 | B20: 7 | C20: 0 | D20: 0 | E20: 0 | F20: 0 | G20: 0 | H20: 0 | I20: 0 | J20: 0 | K20: 0 | L20: 0 | O20: 0 | P20: 0 | Q20: 0 | R20: 0 | T20: 270 | U20: 7 | V20: 0 | W20: 0 | X20: 0 | Y20: 0 | Z20: 0 | AA20: 0 | AB20: 0 | AC20: 0 | AD20: 0 | AE20: 0 | AF20: 0 | AH20: 0 | AI20: 0 | AJ20: 0 | AK20: 0 | AM20: 270 | AN20: 7 | AO20: 1 | AP20: 1 | AQ20: 2787.13 | AR20: 5.4 | AS20: 3 | AT20: 109 | AU20: 15.78 | AV20: 5166 | AW20: 791 | AX20: 299 | AY20: 0 | BA20: 90 | BB20: 610.4 | BC20: 0.885 | BD20: 1.388 | BF20: 270 | BG20: 7 | BH20: 1 | BI20: 1 | BJ20: 2787.13 | BK20: 5.4 | BL20: 3 | BM20: 109 | BN20: 15.78 | BO20: 5166 | BP20: 791 | BQ20: 299 | BR20: 0 | BT20: 90 | BU20: 610.4 | BV20: 0.885 | BW20: 1.388
A21: 270 | B21: 8 | C21: 0 | D21: 0 | E21: 0 | F21: 0 | G21: 0 | H21: 0 | I21: 0 | M21: 0 | O21: 0 | P21: 0 | Q21: 0 | R21: 0 | T21: 270 | U21: 8 | V21: 0 | W21: 0 | X21: 0 | Y21: 0 | Z21: 0 | AA21: 0 | AB21: 0 | AC21: 0 | AD21: 0 | AE21: 0 | AF21: 0 | AH21: 0 | AI21: 0 | AJ21: 0 | AK21: 0 | AM21: 270 | AN21: 8 | AO21: 2 | AP21: 2 | AQ21: 2636.93 | AR21: 23.2 | AS21: -2.76 | AT21: 45 | AU21: 0.35 | AV21: 0 | AW21: 0 | AX21: 0 | AY21: 13043 | BA21: 90 | BB21: 572 | BC21: 1.555 | BD21: 2.203 | BF21: 270 | BG21: 8 | BH21: 2 | BI21: 2 | BJ21: 2636.93 | BK21: 23.2 | BL21: -2.76 | BM21: 45 | BN21: 0.35 | BO21: 0 | BP21: 0 | BQ21: 0 | BR21: 13043 | BT21: 90 | BU21: 572 | BV21: 1.555 | BW21: 2.203
A22: 360 | B22: 9 | C22: 0 | D22: 0 | E22: 0 | F22: 0 | G22: 0 | H22: 0 | I22: 0 | J22: 0 | K22: 0 | L22: 0 | O22: 0 | P22: 0 | Q22: 0 | R22: 0 | T22: 360 | U22: 9 | V22: 0 | W22: 0 | X22: 0 | Y22: 0 | Z22: 0 | AA22: 0 | AB22: 0 | AC22: 0 | AD22: 0 | AE22: 0 | AF22: 0 | AH22: 0 | AI22: 0 | AJ22: 0 | AK22: 0 | AM22: 360 | AN22: 9 | AO22: 1 | AP22: 1 | AQ22: 2787.13 | AR22: 5.4 | AS22: 3 | AT22: 105 | AU22: 15.09 | AV22: 5166 | AW22: 791 | AX22: 299 | AY22: 0 | BA22: 90 | BB22: 612.4 | BC22: 0.885 | BD22: 1.349 | BF22: 360 | BG22: 9 | BH22: 1 | BI22: 1 | BJ22: 2787.13 | BK22: 5.4 | BL22: 3 | BM22: 105 | BN22: 15.09 | BO22: 5166 | BP22: 791 | BQ22: 299 | BR22: 0 | BT22: 90 | BU22: 612.4 | BV22: 0.885 | BW22: 1.349
A23: 360 | B23: 10 | C23: 0 | D23: 0 | E23: 0 | F23: 0 | G23: 0 | H23: 0 | I23: 0 | M23: 0 | O23: 0 | P23: 0 | Q23: 0 | R23: 0 | T23: 360 | U23: 10 | V23: 0 | W23: 0 | X23: 0 | Y23: 0 | Z23: 0 | AA23: 0 | AB23: 0 | AC23: 0 | AD23: 0 | AE23: 0 | AF23: 0 | AH23: 0 | AI23: 0 | AJ23: 0 | AK23: 0 | AM23: 360 | AN23: 10 | AO23: 2 | AP23: 2 | AQ23: 2636.93 | AR23: 23.2 | AS23: -2.76 | AT23: 52 | AU23: 0.4 | AV23: 0 | AW23: 0 | AX23: 0 | AY23: 12997 | BA23: 90 | BB23: 572 | BC23: 1.555 | BD23: 2.246 | BF23: 360 | BG23: 10 | BH23: 2 | BI23: 2 | BJ23: 2636.93 | BK23: 23.2 | BL23: -2.76 | BM23: 52 | BN23: 0.4 | BO23: 0 | BP23: 0 | BQ23: 0 | BR23: 12997 | BT23: 90 | BU23: 572 | BV23: 1.555 | BW23: 2.246
A24: 450 | B24: 11 | C24: 0 | D24: 0 | E24: 0 | F24: 0 | G24: 0 | H24: 0 | I24: 0 | J24: 0 | K24: 0 | L24: 0 | O24: 0 | P24: 0 | Q24: 0 | R24: 0 | T24: 450 | U24: 11 | V24: 0 | W24: 0 | X24: 0 | Y24: 0 | Z24: 0 | AA24: 0 | AB24: 0 | AC24: 0 | AD24: 0 | AE24: 0 | AF24: 0 | AH24: 0 | AI24: 0 | AJ24: 0 | AK24: 0 | AM24: 450 | AN24: 11 | AO24: 1 | AP24: 1 | AQ24: 2787.13 | AR24: 5.4 | AS24: 3 | AT24: 105 | AU24: 15.1 | AV24: 5166 | AW24: 791 | AX24: 299 | AY24: 0 | BA24: 90 | BB24: 609.8 | BC24: 0.885 | BD24: 1.346 | BF24: 450 | BG24: 11 | BH24: 1 | BI24: 1 | BJ24: 2787.13 | BK24: 5.4 | BL24: 3 | BM24: 105 | BN24: 15.1 | BO24: 5166 | BP24: 791 | BQ24: 299 | BR24: 0 | BT24: 90 | BU24: 609.8 | BV24: 0.885 | BW24: 1.346
A25: 450 | B25: 12 | C25: 0 | D25: 0 | E25: 0 | F25: 0 | G25: 0 | H25: 0 | I25: 0 | M25: 0 | O25: 0 | P25: 0 | Q25: 0 | R25: 0 | T25: 450 | U25: 12 | V25: 0 | W25: 0 | X25: 0 | Y25: 0 | Z25: 0 | AA25: 0 | AB25: 0 | AC25: 0 | AD25: 0 | AE25: 0 | AF25: 0 | AH25: 0 | AI25: 0 | AJ25: 0 | AK25: 0 | AM25: 450 | AN25: 12 | AO25: 2 | AP25: 2 | AQ25: 2636.93 | AR25: 23.2 | AS25: -2.76 | AT25: 52 | AU25: 0.4 | AV25: 0 | AW25: 0 | AX25: 0 | AY25: 12997 | BA25: 90 | BB25: 572 | BC25: 1.555 | BD25: 2.245 | BF25: 450 | BG25: 12 | BH25: 2 | BI25: 2 | BJ25: 2636.93 | BK25: 23.2 | BL25: -2.76 | BM25: 52 | BN25: 0.4 | BO25: 0 | BP25: 0 | BQ25: 0 | BR25: 12997 | BT25: 90 | BU25: 572 | BV25: 1.555 | BW25: 2.245
A26: 630 | B26: 15 | C26: 0 | D26: 0 | E26: 0 | F26: 0 | G26: 0 | H26: 0 | I26: 0 | J26: 0 | K26: 0 | L26: 0 | O26: 0 | P26: 0 | Q26: 0 | R26: 0 | T26: 630 | U26: 15 | V26: 0 | W26: 0 | X26: 0 | Y26: 0 | Z26: 0 | AA26: 0 | AB26: 0 | AC26: 0 | AD26: 0 | AE26: 0 | AF26: 0 | AH26: 0 | AI26: 0 | AJ26: 0 | AK26: 0 | AM26: 630 | AN26: 15 | AO26: 1 | AP26: 1 | AQ26: 2787.13 | AR26: 5.4 | AS26: 3 | AT26: 104 | AU26: 14.98 | AV26: 5166 | AW26: 791 | AX26: 299 | AY26: 0 | BA26: 90 | BB26: 611.4 | BC26: 0.885 | BD26: 1.36 | BF26: 630 | BG26: 15 | BH26: 1 | BI26: 1 | BJ26: 2787.13 | BK26: 5.4 | BL26: 3 | BM26: 104 | BN26: 14.98 | BO26: 5166 | BP26: 791 | BQ26: 299 | BR26: 0 | BT26: 90 | BU26: 611.4 | BV26: 0.885 | BW26: 1.36
A27: 630 | B27: 16 | C27: 0 | D27: 0 | E27: 0 | F27: 0 | G27: 0 | H27: 0 | I27: 0 | M27: 0 | O27: 0 | P27: 0 | Q27: 0 | R27: 0 | T27: 630 | U27: 16 | V27: 0 | W27: 0 | X27: 0 | Y27: 0 | Z27: 0 | AA27: 0 | AB27: 0 | AC27: 0 | AD27: 0 | AE27: 0 | AF27: 0 | AH27: 0 | AI27: 0 | AJ27: 0 | AK27: 0 | AM27: 630 | AN27: 16 | AO27: 2 | AP27: 2 | AQ27: 2636.93 | AR27: 23.2 | AS27: -2.76 | AT27: 53 | AU27: 0.41 | AV27: 0 | AW27: 0 | AX27: 0 | AY27: 13043 | BA27: 90 | BB27: 571.8 | BC27: 1.555 | BD27: 2.265 | BF27: 630 | BG27: 16 | BH27: 2 | BI27: 2 | BJ27: 2636.93 | BK27: 23.2 | BL27: -2.76 | BM27: 53 | BN27: 0.41 | BO27: 0 | BP27: 0 | BQ27: 0 | BR27: 13043 | BT27: 90 | BU27: 571.8 | BV27: 1.555 | BW27: 2.265
A28: 720 | B28: 17 | C28: 0 | D28: 0 | E28: 0 | F28: 0 | G28: 0 | H28: 0 | I28: 0 | J28: 0 | K28: 0 | L28: 0 | O28: 0 | P28: 0 | Q28: 0 | R28: 0 | T28: 720 | U28: 17 | V28: 0 | W28: 0 | X28: 0 | Y28: 0 | Z28: 0 | AA28: 0 | AB28: 0 | AC28: 0 | AD28: 0 | AE28: 0 | AF28: 0 | AH28: 0 | AI28: 0 | AJ28: 0 | AK28: 0 | AM28: 720 | AN28: 17 | AO28: 1 | AP28: 1 | AQ28: 2787.13 | AR28: 5.4 | AS28: 3 | AT28: 104 | AU28: 14.98 | AV28: 5166 | AW28: 791 | AX28: 299 | AY28: 0 | BA28: 90 | BB28: 611.4 | BC28: 0.885 | BD28: 1.36 | BF28: 720 | BG28: 17 | BH28: 1 | BI28: 1 | BJ28: 2787.13 | BK28: 5.4 | BL28: 3 | BM28: 104 | BN28: 14.98 | BO28: 5166 | BP28: 791 | BQ28: 299 | BR28: 0 | BT28: 90 | BU28: 611.4 | BV28: 0.885 | BW28: 1.36
A29: 720 | B29: 18 | C29: 0 | D29: 0 | E29: 0 | F29: 0 | G29: 0 | H29: 0 | I29: 0 | M29: 0 | O29: 0 | P29: 0 | Q29: 0 | R29: 0 | T29: 720 | U29: 18 | V29: 0 | W29: 0 | X29: 0 | Y29: 0 | Z29: 0 | AA29: 0 | AB29: 0 | AC29: 0 | AD29: 0 | AE29: 0 | AF29: 0 | AH29: 0 | AI29: 0 | AJ29: 0 | AK29: 0 | AM29: 720 | AN29: 18 | AO29: 2 | AP29: 2 | AQ29: 2636.93 | AR29: 23.2 | AS29: -2.76 | AT29: 53 | AU29: 0.41 | AV29: 0 | AW29: 0 | AX29: 0 | AY29: 13043 | BA29: 90 | BB29: 571.8 | BC29: 1.555 | BD29: 2.265 | BF29: 720 | BG29: 18 | BH29: 2 | BI29: 2 | BJ29: 2636.93 | BK29: 23.2 | BL29: -2.76 | BM29: 53 | BN29: 0.41 | BO29: 0 | BP29: 0 | BQ29: 0 | BR29: 13043 | BT29: 90 | BU29: 571.8 | BV29: 1.555 | BW29: 2.265
A30: 900 | B30: 21 | C30: 0 | D30: 0 | E30: 0 | F30: 0 | G30: 0 | H30: 0 | I30: 0 | J30: 0 | K30: 0 | L30: 0 | O30: 0 | P30: 0 | Q30: 0 | R30: 0 | T30: 900 | U30: 21 | V30: 0 | W30: 0 | X30: 0 | Y30: 0 | Z30: 0 | AA30: 0 | AB30: 0 | AC30: 0 | AD30: 0 | AE30: 0 | AF30: 0 | AH30: 0 | AI30: 0 | AJ30: 0 | AK30: 0 | AM30: 900 | AN30: 21 | AO30: 1 | AP30: 1 | AQ30: 2787.13 | AR30: 5.4 | AS30: 3 | AT30: 104 | AU30: 15.02 | AV30: 5166 | AW30: 791 | AX30: 299 | AY30: 0 | BA30: 90 | BB30: 608.6 | BC30: 0.885 | BD30: 1.359 | BF30: 900 | BG30: 21 | BH30: 1 | BI30: 1 | BJ30: 2787.13 | BK30: 5.4 | BL30: 3 | BM30: 104 | BN30: 15.02 | BO30: 5166 | BP30: 791 | BQ30: 299 | BR30: 0 | BT30: 90 | BU30: 608.6 | BV30: 0.885 | BW30: 1.359
A31: 900 | B31: 22 | C31: 0 | D31: 0 | E31: 0 | F31: 0 | G31: 0 | H31: 0 | I31: 0 | M31: 0 | O31: 0 | P31: 0 | Q31: 0 | R31: 0 | T31: 900 | U31: 22 | V31: 0 | W31: 0 | X31: 0 | Y31: 0 | Z31: 0 | AA31: 0 | AB31: 0 | AC31: 0 | AD31: 0 | AE31: 0 | AF31: 0 | AH31: 0 | AI31: 0 | AJ31: 0 | AK31: 0 | AM31: 900 | AN31: 22 | AO31: 2 | AP31: 2 | AQ31: 2636.93 | AR31: 23.2 | AS31: -2.76 | AT31: 52 | AU31: 0.41 | AV31: 0 | AW31: 0 | AX31: 0 | AY31: 12997 | BA31: 90 | BB31: 571.8 | BC31: 1.555 | BD31: 2.266 | BF31: 900 | BG31: 22 | BH31: 2 | BI31: 2 | BJ31: 2636.93 | BK31: 23.2 | BL31: -2.76 | BM31: 52 | BN31: 0.41 | BO31: 0 | BP31: 0 | BQ31: 0 | BR31: 12997 | BT31: 90 | BU31: 571.8 | BV31: 1.555 | BW31: 2.266
A32: 910 | B32: 21 | C32: 0 | D32: 0 | E32: 0 | F32: 0 | G32: 0 | H32: 0 | I32: 0 | J32: 0 | K32: 0 | L32: 0 | O32: 0 | P32: 0 | Q32: 0 | R32: 0 | T32: 910 | U32: 21 | V32: 0 | W32: 0 | X32: 0 | Y32: 0 | Z32: 0 | AA32: 0 | AB32: 0 | AC32: 0 | AD32: 0 | AE32: 0 | AF32: 0 | AH32: 0 | AI32: 0 | AJ32: 0 | AK32: 0 | AM32: 910 | AN32: 21 | AO32: 1 | AP32: 1 | AQ32: 3078.14 | AR32: 32.38 | AS32: 2.02 | AT32: 1143 | AU32: 4.58 | AV32: 3260 | AW32: 900 | AX32: 959 | AY32: 0 | BA32: 90 | BB32: 599 | BC32: 1.402 | BD32: 2.382 | BF32: 910 | BG32: 21 | BH32: 1 | BI32: 1 | BJ32: 3078.14 | BK32: 32.38 | BL32: 2.02 | BM32: 1143 | BN32: 4.58 | BO32: 3260 | BP32: 900 | BQ32: 959 | BR32: 0 | BT32: 90 | BU32: 599 | BV32: 1.402 | BW32: 2.382
A33: 910 | B33: 22 | C33: 0 | D33: 0 | E33: 0 | M33: 0 | O33: 0 | P33: 0 | Q33: 0 | R33: 0 | T33: 910 | U33: 22 | V33: 0 | W33: 0 | X33: 0 | Y33: 0 | Z33: 0 | AA33: 0 | AB33: 0 | AC33: 0 | AD33: 0 | AE33: 0 | AF33: 0 | AH33: 0 | AI33: 0 | AJ33: 0 | AK33: 0 | AM33: 910 | AN33: 22 | AO33: 2 | AP33: 2 | AQ33: 2780 | AR33: 0 | AS33: 0 | AT33: 0 | AU33: 0 | AV33: 0 | AW33: 0 | AX33: 0 | AY33: 13829 | BA33: 90 | BB33: 566 | BC33: 0.408 | BD33: 0.833 | BF33: 910 | BG33: 22 | BH33: 2 | BI33: 2 | BJ33: 2780 | BK33: 0 | BL33: 0 | BM33: 0 | BN33: 0 | BO33: 0 | BP33: 0 | BQ33: 0 | BR33: 13829 | BT33: 90 | BU33: 566 | BV33: 0.408 | BW33: 0.833
A34: 910 | B34: 23 | C34: 0 | D34: 0 | E34: 0 | F34: 0 | G34: 0 | H34: 0 | I34: 0 | J34: 0 | K34: 0 | L34: 0 | O34: 0 | P34: 0 | Q34: 0 | R34: 0 | T34: 910 | U34: 23 | V34: 0 | W34: 0 | X34: 0 | Y34: 0 | Z34: 0 | AA34: 0 | AB34: 0 | AC34: 0 | AD34: 0 | AE34: 0 | AF34: 0 | AH34: 0 | AI34: 0 | AJ34: 0 | AK34: 0 | AM34: 910 | AN34: 23 | AO34: 1 | AP34: 1 | AQ34: 213.41 | AR34: 28.3 | AS34: 2.19 | AT34: 337 | AU34: 1.77 | AV34: 3744 | AW34: 900 | AX34: 959 | AY34: 0 | BA34: 90 | BB34: 617.6 | BC34: 1.346 | BD34: 2.161 | BF34: 910 | BG34: 23 | BH34: 1 | BI34: 1 | BJ34: 213.41 | BK34: 28.3 | BL34: 2.19 | BM34: 337 | BN34: 1.77 | BO34: 3744 | BP34: 900 | BQ34: 959 | BR34: 0 | BT34: 90 | BU34: 617.6 | BV34: 1.346 | BW34: 2.161
A35: 920 | B35: 21 | C35: 0 | D35: 0 | E35: 0 | F35: 0 | G35: 0 | H35: 0 | I35: 0 | O35: 0 | P35: 0 | Q35: 0 | R35: 0 | T35: 920 | U35: 21 | V35: 0 | W35: 0 | X35: 0 | Y35: 0 | Z35: 0 | AA35: 0 | AB35: 0 | AC35: 0 | AD35: 0 | AE35: 0 | AF35: 0 | AH35: 0 | AI35: 0 | AJ35: 0 | AK35: 0 | AM35: 920 | AN35: 21 | AO35: 1 | AP35: 1 | AQ35: 3674.19 | AR35: 44.89 | AS35: -0.1 | AT35: 1829 | AU35: 3.81 | AV35: 0 | AW35: 0 | AX35: 0 | AY35: 0 | BA35: 90 | BB35: 585.9 | BC35: 0.711 | BD35: 1.825 | BF35: 920 | BG35: 21 | BH35: 1 | BI35: 1 | BJ35: 3674.19 | BK35: 44.89 | BL35: -0.1 | BM35: 1829 | BN35: 3.81 | BO35: 0 | BP35: 0 | BQ35: 0 | BR35: 0 | BT35: 90 | BU35: 585.9 | BV35: 0.711 | BW35: 1.825
A36: 920 | B36: 22 | C36: 0 | D36: 0 | E36: 0 | M36: 0 | O36: 0 | P36: 0 | Q36: 0 | R36: 0 | T36: 920 | U36: 22 | V36: 0 | W36: 0 | X36: 0 | Y36: 0 | Z36: 0 | AA36: 0 | AB36: 0 | AC36: 0 | AD36: 0 | AE36: 0 | AF36: 0 | AH36: 0 | AI36: 0 | AJ36: 0 | AK36: 0 | AM36: 920 | AN36: 22 | AO36: 2 | AP36: 2 | AQ36: 2780 | AR36: 0 | AS36: 0 | AT36: 0 | AU36: 0 | AV36: 0 | AW36: 0 | AX36: 0 | AY36: 13829 | BA36: 90 | BB36: 560.8 | BC36: 0.408 | BD36: 0.826 | BF36: 920 | BG36: 22 | BH36: 2 | BI36: 2 | BJ36: 2780 | BK36: 0 | BL36: 0 | BM36: 0 | BN36: 0 | BO36: 0 | BP36: 0 | BQ36: 0 | BR36: 13829 | BT36: 90 | BU36: 560.8 | BV36: 0.408 | BW36: 0.826
A37: 920 | B37: 23 | C37: 0 | D37: 0 | E37: 0 | F37: 0 | G37: 0 | H37: 0 | I37: 0 | J37: 0 | K37: 0 | L37: 0 | O37: 0 | P37: 0 | Q37: 0 | R37: 0 | T37: 920 | U37: 23 | V37: 0 | W37: 0 | X37: 0 | Y37: 0 | Z37: 0 | AA37: 0 | AB37: 0 | AC37: 0 | AD37: 0 | AE37: 0 | AF37: 0 | AH37: 0 | AI37: 0 | AJ37: 0 | AK37: 0 | AM37: 920 | AN37: 23 | AO37: 1 | AP37: 1 | AQ37: 758.44 | AR37: 44.59 | AS37: 1.28 | AT37: 846 | AU37: 1.79 | AV37: 2309 | AW37: 900 | AX37: 959 | AY37: 0 | BA37: 90 | BB37: 606.2 | BC37: 1.464 | BD37: 2.463 | BF37: 920 | BG37: 23 | BH37: 1 | BI37: 1 | BJ37: 758.44 | BK37: 44.59 | BL37: 1.28 | BM37: 846 | BN37: 1.79 | BO37: 2309 | BP37: 900 | BQ37: 959 | BR37: 0 | BT37: 90 | BU37: 606.2 | BV37: 1.464 | BW37: 2.463
A38: 930 | B38: 21 | C38: 0 | D38: 0 | E38: 0 | F38: 0 | G38: 0 | H38: 0 | I38: 0 | O38: 0 | P38: 0 | Q38: 0 | R38: 0 | T38: 930 | U38: 21 | V38: 0 | W38: 0 | X38: 0 | Y38: 0 | Z38: 0 | AA38: 0 | AB38: 0 | AC38: 0 | AD38: 0 | AE38: 0 | AF38: 0 | AH38: 0 | AI38: 0 | AJ38: 0 | AK38: 0 | AM38: 930 | AN38: 21 | AO38: 1 | AP38: 1 | AQ38: 4321 | AR38: 43.32 | AS38: -0.14 | AT38: 992 | AU38: 2.22 | AV38: 0 | AW38: 0 | AX38: 0 | AY38: 0 | BA38: 90 | BB38: 573 | BC38: 0.699 | BD38: 1.668 | BF38: 930 | BG38: 21 | BH38: 1 | BI38: 1 | BJ38: 4321 | BK38: 43.32 | BL38: -0.14 | BM38: 992 | BN38: 2.22 | BO38: 0 | BP38: 0 | BQ38: 0 | BR38: 0 | BT38: 90 | BU38: 573 | BV38: 0.699 | BW38: 1.668
A39: 930 | B39: 22 | C39: 0 | D39: 0 | E39: 0 | M39: 0 | O39: 0 | P39: 0 | Q39: 0 | R39: 0 | T39: 930 | U39: 22 | V39: 0 | W39: 0 | X39: 0 | Y39: 0 | Z39: 0 | AA39: 0 | AB39: 0 | AC39: 0 | AD39: 0 | AE39: 0 | AF39: 0 | AH39: 0 | AI39: 0 | AJ39: 0 | AK39: 0 | AM39: 930 | AN39: 22 | AO39: 2 | AP39: 2 | AQ39: 2780 | AR39: 0 | AS39: 0 | AT39: 0 | AU39: 0 | AV39: 0 | AW39: 0 | AX39: 0 | AY39: 13829 | BA39: 90 | BB39: 555.8 | BC39: 0.408 | BD39: 0.82 | BF39: 930 | BG39: 22 | BH39: 2 | BI39: 2 | BJ39: 2780 | BK39: 0 | BL39: 0 | BM39: 0 | BN39: 0 | BO39: 0 | BP39: 0 | BQ39: 0 | BR39: 13829 | BT39: 90 | BU39: 555.8 | BV39: 0.408 | BW39: 0.82
A40: 930 | B40: 23 | C40: 0 | D40: 0 | E40: 0 | F40: 0 | G40: 0 | H40: 0 | I40: 0 | O40: 0 | P40: 0 | Q40: 0 | R40: 0 | T40: 930 | U40: 23 | V40: 0 | W40: 0 | X40: 0 | Y40: 0 | Z40: 0 | AA40: 0 | AB40: 0 | AC40: 0 | AD40: 0 | AE40: 0 | AF40: 0 | AH40: 0 | AI40: 0 | AJ40: 0 | AK40: 0 | AM40: 930 | AN40: 23 | AO40: 1 | AP40: 1 | AQ40: 1463.4 | AR40: 44.94 | AS40: -0.2 | AT40: 828 | AU40: 1.72 | AV40: 0 | AW40: 0 | AX40: 0 | AY40: 0 | BA40: 90 | BB40: 605.5 | BC40: 0.682 | BD40: 1.711 | BF40: 930 | BG40: 23 | BH40: 1 | BI40: 1 | BJ40: 1463.4 | BK40: 44.94 | BL40: -0.2 | BM40: 828 | BN40: 1.72 | BO40: 0 | BP40: 0 | BQ40: 0 | BR40: 0 | BT40: 90 | BU40: 605.5 | BV40: 0.682 | BW40: 1.711
...

Sheet SEG
A1: Next-Vis Sheet: SEG
A2: Summary
A3: Percent Error = Absolute value of [(Difference) / (4p2\normal.PRN)] x 100% | T3: Difference = (4p2\normal4p2.out) - (4p2\normal.PRN)
C4: A_Max | D4: A_Max_T | E4: A_Min | F4: A_Min_T | G4: A_P | H4: A_N | I4: V_Max | J4: V_Max_T | K4: V_Min | L4: V_Min_T | M4: V_P | N4: V_N | O4: A_P_P | P4: A_P_N | Q4: V_E | R4: V_EP | V4: A_Max | W4: A_Max_T | X4: A_Min | Y4: A_Min_T | Z4: A_P | AA4: A_N | AB4: V_Max | AC4: V_Max_T | AD4: V_Min | AE4: V_Min_T | AF4: V_P | AG4: V_N | AH4: A_P_P | AI4: A_P_N | AJ4: V_E | AK4: V_EP
B5: count | C5: 72 | D5: 72 | E5: 72 | F5: 72 | G5: 56 | H5: 56 | I5: 72 | J5: 72 | K5: 72 | L5: 72 | M5: 56 | N5: 56 | O5: 56 | P5: 56 | Q5: 16 | R5: 12 | U5: count | V5: 72 | W5: 72 | X5: 72 | Y5: 72 | Z5: 72 | AA5: 72 | AB5: 72 | AC5: 72 | AD5: 72 | AE5: 72 | AF5: 72 | AG5: 72 | AH5: 72 | AI5: 72 | AJ5: 72 | AK5: 72
B6: mean | C6: 6.6743937e-05 | D6: 0 | E6: 0.00049106908 | F6: 0 | G6: 0.00025307498 | H6: 3.9470916e-05 | I6: 0 | J6: 0 | K6: 0 | L6: 0 | M6: 0 | N6: 0 | O6: 0 | P6: 0 | Q6: 0 | R6: 0 | U6: mean | V6: 5.5555556e-05 | W6: 0 | X6: 0.00022222222 | Y6: 0 | Z6: 8.3333333e-05 | AA6: 5.5555556e-05 | AB6: 0 | AC6: 0 | AD6: 0 | AE6: 0 | AF6: 0 | AG6: 0 | AH6: 0 | AI6: 0 | AJ6: 0 | AK6: 0
B7: std | C7: 0.0002413432 | D7: 0 | E7: 0.0011933927 | F7: 0 | G7: 0.00090049161 | H7: 0.00014802174 | I7: 0 | J7: 0 | K7: 0 | L7: 0 | M7: 0 | N7: 0 | O7: 0 | P7: 0 | Q7: 0 | R7: 0 | U7: std | V7: 0.00028526681 | W7: 0 | X7: 0.00053660965 | Y7: 0 | Z7: 0.00032501354 | AA7: 0.00023066889 | AB7: 0 | AC7: 0 | AD7: 0 | AE7: 0 | AF7: 0 | AG7: 0 | AH7: 0 | AI7: 0 | AJ7: 0 | AK7: 0
B8: min | C8: 0 | D8: 0 | E8: 0 | F8: 0 | G8: 0 | H8: 0 | I8: 0 | J8: 0 | K8: 0 | L8: 0 | M8: 0 | N8: 0 | O8: 0 | P8: 0 | Q8: 0 | R8: 0 | U8: min | V8: -0.001 | W8: 0 | X8: -0.001 | Y8: 0 | Z8: -0.001 | AA8: 0 | AB8: 0 | AC8: 0 | AD8: 0 | AE8: 0 | AF8: 0 | AG8: 0 | AH8: 0 | AI8: 0 | AJ8: 0 | AK8: 0
B9: 25% | C9: 0 | D9: 0 | E9: 0 | F9: 0 | G9: 0 | H9: 0 | I9: 0 | J9: 0 | K9: 0 | L9: 0 | M9: 0 | N9: 0 | O9: 0 | P9: 0 | Q9: 0 | R9: 0 | U9: 25% | V9: 0 | W9: 0 | X9: 0 | Y9: 0 | Z9: 0 | AA9: 0 | AB9: 0 | AC9: 0 | AD9: 0 | AE9: 0 | AF9: 0 | AG9: 0 | AH9: 0 | AI9: 0 | AJ9: 0 | AK9: 0
B10: 50% | C10: 0 | D10: 0 | E10: 0 | F10: 0 | G10: 0 | H10: 0 | I10: 0 | J10: 0 | K10: 0 | L10: 0 | M10: 0 | N10: 0 | O10: 0 | P10: 0 | Q10: 0 | R10: 0 | U10: 50% | V10: 0 | W10: 0 | X10: 0 | Y10: 0 | Z10: 0 | AA10: 0 | AB10: 0 | AC10: 0 | AD10: 0 | AE10: 0 | AF10: 0 | AG10: 0 | AH10: 0 | AI10: 0 | AJ10: 0 | AK10: 0
B11: 75% | C11: 0 | D11: 0 | E11: 0.00023424854 | F11: 0 | G11: 0 | H11: 0 | I11: 0 | J11: 0 | K11: 0 | L11: 0 | M11: 0 | N11: 0 | O11: 0 | P11: 0 | Q11: 0 | R11: 0 | U11: 75% | V11: 0 | W11: 0 | X11: 0.00025 | Y11: 0 | Z11: 0 | AA11: 0 | AB11: 0 | AC11: 0 | AD11: 0 | AE11: 0 | AF11: 0 | AG11: 0 | AH11: 0 | AI11: 0 | AJ11: 0 | AK11: 0
